Workbook

Sheet Kendaraan
B2: Client | E2: : | F2: =#REF! -> #REF!
B3: Period | E3: : | F3: 44196
B4: Schedule | E4: : | F4: Tes Perhitungan Beban Penyusutan Aset Tetap
B6: No | C6: Tanggal Perolehan | E6: Deskripsi | G6: Tarif | I6: Harga Perolehan | M6: PAJE/CAJE/RJE | P6: Life | T6: Beginning of Depreciation | V6: Ending of Depreciation | X6: Penyusutan per Bulan | AA6: 44926 | AF6: 45291 | AK6: 45657 | AP6: 46022 | AU6: 46387
D7: Tanggal TA | I7: 43100 | J7: Penambahan | K7: Pengurangan | L7: 43465 | M7: Dr | N7: Cr | O7: =L7 -> 43465 | P7: Awal | R7: Penyesuaian | T7: Month | U7: Year | V7: Month | W7: Year | AA7: Bulan | AB7: Beban Penyusutan | AC7: Akumulasi Penyusutan | AD7: Nilai Buku | AF7: Bulan | AG7: Beban Penyusutan | AH7: Akumulasi Penyusutan | AI7: Nilai Buku | AK7: Bulan | AL7: Beban Penyusutan | AM7: Akumulasi Penyusutan | AN7: Nilai Buku | AP7: Bulan | AQ7: Beban Penyusutan | AR7: Akumulasi Penyusutan | AS7: Nilai Buku | AU7: Bulan | AV7: Beban Penyusutan | AW7: Akumulasi Penyusutan | AX7: Nilai Buku | AZ7: TOTAL | BA7: JAN | BB7: FEB | BC7: MAR | BD7: APR | BE7: MAY | BF7: JUNE | BG7: JUL | BH7: AUG | BI7: SEP | BJ7: OCT | BK7: NOV | BL7: DEC
G8: Awal | H8: Penyesuaian | L8: Unaudited | O8: Audited | P8: Year | Q8: Month | R8: Year | S8: Month | X8: Awal | Y8: Penyesuaian | AZ8: 2026
C10: Kendaraan
C12: 41243 | E12: Toyota Kijang Inova Diesel B 1022 KOF | G12: 0.25 | H12: 0.125 | I12: 278911510 | L12: =I12+J12-K12 -> 278911510 | O12: =L12+M12-N12 -> 278911510 | P12: =100%/G12 -> 4 | Q12: =P12*12 -> 48 | R12: =100%/H12 -> 8 | S12: =R12*12 -> 96 | T12: =MONTH(C12) -> 11 | U12: =YEAR(C12) -> 2012 | V12: =IF(T12=1, 12, T12-1) -> 10 | W12: =IF(T12=1,U12+R12-1,U12+R12) -> 2020 | X12: =I12/Q12 -> 5810656.5 | AA12: 0 | AB12: 0 | AC12: 278911510 | AD12: =O12-AC12 -> 0 | AF12: 0 | AG12: =AF12*AB12 -> 0 | AH12: =AC12+AG12 -> 278911510 | AI12: =O12-AH12 -> 0 | AK12: 0 | AL12: =AK12*Y12 -> 0 | AM12: =AH12+AL12 -> 278911510 | AN12: =O12-AM12 -> 0 | AP12: 0 | AQ12: =AP12*AD12 -> 0 | AR12: =AM12+AQ12 -> 278911510 | AS12: =O12-AR12 -> 0 | AU12: 0 | AV12: =AU12*AI12 -> 0 | AW12: =AR12+AV12 -> 278911510 | AX12: =O12-AW12 -> 0 | AZ12: =SUM(BA12:BL12) -> 0 | BA12: =+Y12*0 -> 0 | BB12: =+Y12*0 -> 0 | BC12: =+Y12*0 -> 0 | BD12: =+Y12*0 -> 0 | BE12: =+Y12*0 -> 0 | BF12: =+Y12*0 -> 0 | BG12: =+Y12*0 -> 0 | BH12: =+Y12*0 -> 0 | BI12: =+Y12*0 -> 0 | BJ12: =+Y12*0 -> 0 | BK12: =+Y12*0 -> 0 | BL12: =+Y12*0 -> 0
C13: 41243 | E13: Toyota Avanza Veloz B.1024 KOF | G13: 0.25 | H13: 0.125 | I13: 193897458 | L13: =I13+J13-K13 -> 193897458 | O13: =L13+M13-N13 -> 193897458 | P13: =100%/G13 -> 4 | Q13: =P13*12 -> 48 | R13: =100%/H13 -> 8 | S13: =R13*12 -> 96 | T13: =MONTH(C13) -> 11 | U13: =YEAR(C13) -> 2012 | V13: =IF(T13=1, 12, T13-1) -> 10 | W13: =IF(T13=1,U13+R13-1,U13+R13) -> 2020 | X13: =I13/Q13 -> 4039530.4 | AA13: 0 | AB13: 0 | AC13: 193897458 | AD13: =O13-AC13 -> 0 | AF13: 0 | AG13: =AF13*AB13 -> 0 | AH13: =AC13+AG13 -> 193897458 | AI13: =O13-AH13 -> 0 | AK13: 0 | AL13: =AK13*Y13 -> 0 | AM13: =AH13+AL13 -> 193897458 | AN13: =O13-AM13 -> 0 | AP13: 0 | AQ13: =AP13*AD13 -> 0 | AR13: 0 | AS13: 0 | AU13: 0 | AV13: =AU13*AI13 -> 0 | AW13: 0 | AX13: 0 | AZ13: =SUM(BA13:BL13) -> 0 | BA13: =+Y13*0 -> 0 | BB13: =+Y13*0 -> 0 | BC13: =+Y13*0 -> 0 | BD13: =+Y13*0 -> 0 | BE13: =+Y13*0 -> 0 | BF13: =+Y13*0 -> 0 | BG13: =+Y13*0 -> 0 | BH13: =+Y13*0 -> 0 | BI13: =+Y13*0 -> 0 | BJ13: =+Y13*0 -> 0 | BK13: =+Y13*0 -> 0 | BL13: =+Y13*0 -> 0
C14: 41243 | E14: Toyota Avanza 1,5 G B 1023 KOF | G14: 0.25 | H14: 0.125 | I14: 176885845 | L14: =I14+J14-K14 -> 176885845 | O14: =L14+M14-N14 -> 176885845 | P14: =100%/G14 -> 4 | Q14: =P14*12 -> 48 | R14: =100%/H14 -> 8 | S14: =R14*12 -> 96 | T14: =MONTH(C14) -> 11 | U14: =YEAR(C14) -> 2012 | V14: =IF(T14=1, 12, T14-1) -> 10 | W14: =IF(T14=1,U14+R14-1,U14+R14) -> 2020 | X14: =I14/Q14 -> 3685121.8 | AA14: 0 | AB14: 0 | AC14: 176885845 | AD14: =O14-AC14 -> 0 | AF14: 0 | AG14: =AF14*AB14 -> 0 | AH14: =AC14+AG14 -> 176885845 | AI14: =O14-AH14 -> 0 | AK14: 0 | AL14: =AK14*Y14 -> 0 | AM14: =AH14+AL14 -> 176885845 | AN14: =O14-AM14 -> 0 | AP14: 0 | AQ14: =AP14*AD14 -> 0 | AR14: 0 | AS14: 0 | AU14: 0 | AV14: =AU14*AI14 -> 0 | AW14: 0 | AX14: 0 | AZ14: =SUM(BA14:BL14) -> 0 | BA14: =+Y14*0 -> 0 | BB14: =+Y14*0 -> 0 | BC14: =+Y14*0 -> 0 | BD14: =+Y14*0 -> 0 | BE14: =+Y14*0 -> 0 | BF14: =+Y14*0 -> 0 | BG14: =+Y14*0 -> 0 | BH14: =+Y14*0 -> 0 | BI14: =+Y14*0 -> 0 | BJ14: =+Y14*0 -> 0 | BK14: =+Y14*0 -> 0 | BL14: =+Y14*0 -> 0
C15: 41248 | E15: Toyota Avanza 1,5 G B 1002 KOG | G15: 0.25 | H15: 0.125 | I15: 175911139 | L15: =I15+J15-K15 -> 175911139 | O15: =L15+M15-N15 -> 175911139 | P15: =100%/G15 -> 4 | Q15: =P15*12 -> 48 | R15: =100%/H15 -> 8 | S15: =R15*12 -> 96 | T15: =MONTH(C15) -> 12 | U15: =YEAR(C15) -> 2012 | V15: =IF(T15=1, 12, T15-1) -> 11 | W15: =IF(T15=1,U15+R15-1,U15+R15) -> 2020 | X15: =I15/Q15 -> 3664815.4 | AA15: 0 | AB15: 0 | AC15: 175911139 | AD15: =O15-AC15 -> 0 | AF15: 0 | AG15: =AF15*AB15 -> 0 | AH15: =AC15+AG15 -> 175911139 | AI15: =O15-AH15 -> 0 | AK15: 0 | AL15: =AK15*Y15 -> 0 | AM15: =AH15+AL15 -> 175911139 | AN15: =O15-AM15 -> 0 | AQ15: =AP15*AD15 -> 0 | AR15: 0 | AS15: 0 | AV15: =AU15*AI15 -> 0 | AW15: 0 | AX15: 0 | AZ15: =SUM(BA15:BL15) -> 0 | BA15: =+Y15*0 -> 0 | BB15: =+Y15*0 -> 0 | BC15: =+Y15*0 -> 0 | BD15: =+Y15*0 -> 0 | BE15: =+Y15*0 -> 0 | BF15: =+Y15*0 -> 0 | BG15: =+Y15*0 -> 0 | BH15: =+Y15*0 -> 0 | BI15: =+Y15*0 -> 0 | BJ15: =+Y15*0 -> 0 | BK15: =+Y15*0 -> 0 | BL15: =+Y15*0 -> 0
C16: 41320 | E16: Motor Honda B 3576 KJO | G16: 0.25 | H16: 0.125 | I16: 11760273 | L16: =I16+J16-K16 -> 11760273 | O16: =L16+M16-N16 -> 11760273 | P16: =100%/G16 -> 4 | Q16: =P16*12 -> 48 | R16: =100%/H16 -> 8 | S16: =R16*12 -> 96 | T16: =MONTH(C16) -> 2 | U16: =YEAR(C16) -> 2013 | V16: =IF(T16=1, 12, T16-1) -> 1 | W16: =IF(T16=1,U16+R16-1,U16+R16) -> 2021 | X16: =I16/Q16 -> 245005.69 | Y16: 5000.1161 | AA16: 0 | AB16: 0 | AC16: 11760273 | AD16: =O16-AC16 -> 0 | AF16: 0 | AG16: =AF16*AB16 -> 0 | AH16: =AC16+AG16 -> 11760273 | AI16: =O16-AH16 -> 0 | AK16: 0 | AL16: =AK16*Y16 -> 0 | AM16: =AH16+AL16 -> 11760273 | AN16: =O16-AM16 -> 0 | AP16: 0 | AQ16: =AP16*AD16 -> 0 | AR16: =AM16+AQ16 -> 11760273 | AS16: =O16-AR16 -> 0 | AU16: 0 | AV16: =AU16*AI16 -> 0 | AW16: =AR16+AV16 -> 11760273 | AX16: =O16-AW16 -> 0 | AZ16: =SUM(BA16:BL16) -> 0 | BA16: =+Y16*0 -> 0 | BB16: =+Y16*0 -> 0 | BC16: =+Y16*0 -> 0 | BD16: =+Y16*0 -> 0 | BE16: =+Y16*0 -> 0 | BF16: =+Y16*0 -> 0 | BG16: =+Y16*0 -> 0 | BH16: =+Y16*0 -> 0 | BI16: =+Y16*0 -> 0 | BJ16: =+Y16*0 -> 0 | BK16: =+Y16*0 -> 0 | BL16: =+Y16*0 -> 0
C17: 41339 | E17: Motor Supra X B 3963 KJI | G17: 0.25 | H17: 0.125 | I17: 11893636 | L17: =I17+J17-K17 -> 11893636 | O17: =L17+M17-N17 -> 11893636 | P17: =100%/G17 -> 4 | Q17: =P17*12 -> 48 | R17: =100%/H17 -> 8 | S17: =R17*12 -> 96 | T17: =MONTH(C17) -> 3 | U17: =YEAR(C17) -> 2013 | V17: =IF(T17=1, 12, T17-1) -> 2 | W17: =IF(T17=1,U17+R17-1,U17+R17) -> 2021 | X17: =I17/Q17 -> 247784.08 | Y17: 9911.3633 | AA17: 0 | AB17: 0 | AC17: 11893636 | AD17: =O17-AC17 -> 0 | AF17: 0 | AG17: =AF17*AB17 -> 0 | AH17: =AC17+AG17 -> 11893636 | AI17: =O17-AH17 -> 0 | AK17: 0 | AL17: =AK17*Y17 -> 0 | AM17: =AH17+AL17 -> 11893636 | AN17: =O17-AM17 -> 0 | AP17: 0 | AQ17: =AP17*AD17 -> 0 | AR17: =AM17+AQ17 -> 11893636 | AS17: =O17-AR17 -> 0 | AU17: 0 | AV17: =AU17*AI17 -> 0 | AW17: =AR17+AV17 -> 11893636 | AX17: =O17-AW17 -> 0 | AZ17: =SUM(BA17:BL17) -> 0 | BA17: =+Y17*0 -> 0 | BB17: =+Y17*0 -> 0 | BC17: =+Y17*0 -> 0 | BD17: =+Y17*0 -> 0 | BE17: =+Y17*0 -> 0 | BF17: =+Y17*0 -> 0 | BG17: =+Y17*0 -> 0 | BH17: =+Y17*0 -> 0 | BI17: =+Y17*0 -> 0 | BJ17: =+Y17*0 -> 0 | BK17: =+Y17*0 -> 0 | BL17: =+Y17*0 -> 0
C18: 42727 | E18: Mobil HRV | G18: 0.25 | H18: 0.125 | I18: 321312180 | L18: =I18+J18-K18 -> 321312180 | O18: =L18+M18-N18 -> 321312180 | P18: =100%/G18 -> 4 | Q18: =P18*12 -> 48 | R18: =100%/H18 -> 8 | S18: =R18*12 -> 96 | T18: =MONTH(C18) -> 12 | U18: =YEAR(C18) -> 2016 | V18: =IF(T18=1, 12, T18-1) -> 11 | W18: =IF(T18=1,U18+R18-1,U18+R18) -> 2024 | X18: =I18/Q18 -> 6694003.8 | Y18: 3311770.3 | Z18: 35 | AA18: 12 | AB18: =AA18*Y18 -> 39741243 | AC18: 2.4514146e+08 | AD18: =O18-AC18 -> 76170716 | AE18: =+Z18-AA18 -> 23 | AF18: 12 | AG18: =AF18*Y18 -> 39741243 | AH18: =AC18+AG18 -> 2.8488271e+08 | AI18: =O18-AH18 -> 36429473 | AJ18: =+AE18-AF18 -> 11 | AK18: 11 | AL18: =AK18*Y18 -> 36429473 | AM18: =AH18+AL18 -> 321312180 | AN18: =O18-AM18 -> 0 | AO18: =+AJ18-AK18 -> 0 | AP18: 0 | AQ18: =AP18*AD18 -> 0 | AR18: =AM18+AQ18 -> 321312180 | AS18: =O18-AR18 -> 0 | AT18: =+AO18-AP18 -> 0 | AU18: 0 | AV18: =AU18*AI18 -> 0 | AW18: =AR18+AV18 -> 321312180 | AX18: =O18-AW18 -> 0 | AZ18: =SUM(BA18:BL18) -> 0 | BA18: =+Y18*0 -> 0 | BB18: =+Y18*0 -> 0 | BC18: =+Y18*0 -> 0 | BD18: =+Y18*0 -> 0 | BE18: =+Y18*0 -> 0 | BF18: =+Y18*0 -> 0 | BG18: =+Y18*0 -> 0 | BH18: =+Y18*0 -> 0 | BI18: =+Y18*0 -> 0 | BJ18: =+Y18*0 -> 0 | BK18: =+Y18*0 -> 0 | BL18: =+Y18*0 -> 0
C20: 42830 | E20: 1 | F20: Motor Honda Vario 150 ESP | G20: 0.25 | H20: 0.125 | I20: 21975000 | L20: =I20+J20-K20 -> 21975000 | O20: =L20+M20-N20 -> 21975000 | P20: =100%/G20 -> 4 | Q20: =P20*12 -> 48 | R20: =100%/H20 -> 8 | S20: =R20*12 -> 96 | T20: =MONTH(C20) -> 4 | U20: =YEAR(C20) -> 2017 | V20: =IF(T20=1, 12, T20-1) -> 3 | W20: =IF(T20=1,U20+R20-1,U20+R20) -> 2025 | X20: 0 | Y20: =L20/S20 -> 228906.25 | Z20: 39 | AA20: 12 | AB20: =AA20*Y20 -> 2746875 | AC20: 15794531 | AD20: =O20-AC20 -> 6180468.8 | AE20: =+Z20-AA20 -> 27 | AF20: 12 | AG20: =AF20*Y20 -> 2746875 | AH20: =AC20+AG20 -> 18541406 | AI20: =O20-AH20 -> 3433593.8 | AJ20: =+AE20-AF20 -> 15 | AK20: 12 | AL20: =AK20*Y20 -> 2746875 | AM20: =AH20+AL20 -> 21288281 | AN20: =O20-AM20 -> 686718.75 | AO20: =+AJ20-AK20 -> 3 | AP20: 3 | AQ20: =AP20*Y20 -> 686718.75 | AR20: =AM20+AQ20 -> 21975000 | AS20: =O20-AR20 -> 0 | AT20: =+AO20-AP20 -> 0 | AU20: 0 | AV20: =AU20*AD20 -> 0 | AW20: =AR20+AV20 -> 21975000 | AX20: =O20-AW20 -> 0 | AZ20: =SUM(BA20:BL20) -> 0 | BA20: =+Y20*0 -> 0 | BB20: =+Y20*0 -> 0 | BC20: =+Y20*0 -> 0 | BD20: =+Y20*0 -> 0 | BE20: =+Y20*0 -> 0 | BF20: =+Y20*0 -> 0 | BG20: =+Y20*0 -> 0 | BH20: =+Y20*0 -> 0 | BI20: =+Y20*0 -> 0 | BJ20: =+Y20*0 -> 0 | BK20: =+Y20*0 -> 0 | BL20: =+Y20*0 -> 0
C21: 42940 | E21: 1 | F21: Mobil Grand Max (PT.Tam) | G21: 0.25 | H21: 0.125 | I21: 159575520 | L21: =I21+J21-K21 -> 159575520 | O21: =L21+M21-N21 -> 159575520 | P21: =100%/G21 -> 4 | Q21: =P21*12 -> 48 | R21: =100%/H21 -> 8 | S21: =R21*12 -> 96 | T21: =MONTH(C21) -> 7 | U21: =YEAR(C21) -> 2017 | V21: =IF(T21=1, 12, T21-1) -> 6 | W21: =IF(T21=1,U21+R21-1,U21+R21) -> 2025 | X21: 0 | Y21: =L21/S21 -> 1662245 | Z21: 42 | AA21: 12 | AB21: =AA21*Y21 -> 19946940 | AC21: 109708170 | AD21: =O21-AC21 -> 49867350 | AE21: =+Z21-AA21 -> 30 | AF21: 12 | AG21: =AF21*Y21 -> 19946940 | AH21: =AC21+AG21 -> 129655110 | AI21: =O21-AH21 -> 29920410 | AJ21: =+AE21-AF21 -> 18 | AK21: 12 | AL21: =AK21*Y21 -> 19946940 | AM21: =AH21+AL21 -> 149602050 | AN21: =O21-AM21 -> 9973470 | AO21: =+AJ21-AK21 -> 6 | AP21: 6 | AQ21: =AP21*Y21 -> 9973470 | AR21: =AM21+AQ21 -> 159575520 | AS21: =O21-AR21 -> 0 | AT21: =+AO21-AP21 -> 0 | AU21: 0 | AV21: =AU21*AD21 -> 0 | AW21: =AR21+AV21 -> 159575520 | AX21: =O21-AW21 -> 0 | AZ21: =SUM(BA21:BL21) -> 0 | BA21: =+Y21*0 -> 0 | BB21: =+Y21*0 -> 0 | BC21: =+Y21*0 -> 0 | BD21: =+Y21*0 -> 0 | BE21: =+Y21*0 -> 0 | BF21: =+Y21*0 -> 0 | BG21: =+Y21*0 -> 0 | BH21: =+Y21*0 -> 0 | BI21: =+Y21*0 -> 0 | BJ21: =+Y21*0 -> 0 | BK21: =+Y21*0 -> 0 | BL21: =+Y21*0 -> 0
C22: 42998 | E22: 1 | F22: Kijang Inova | G22: 0.25 | H22: 0.125 | I22: 350363636 | L22: =I22+J22-K22 -> 350363636 | O22: =L22+M22-N22 -> 350363636 | P22: =100%/G22 -> 4 | Q22: =P22*12 -> 48 | R22: =100%/H22 -> 8 | S22: =R22*12 -> 96 | T22: =MONTH(C22) -> 9 | U22: =YEAR(C22) -> 2017 | V22: =IF(T22=1, 12, T22-1) -> 8 | W22: =IF(T22=1,U22+R22-1,U22+R22) -> 2025 | X22: 0 | Y22: =L22/S22 -> 3649621.2 | Z22: 44 | AA22: 12 | AB22: =AA22*Y22 -> 43795454 | AC22: 2.3357576e+08 | AD22: =O22-AC22 -> 1.1678788e+08 | AE22: =+Z22-AA22 -> 32 | AF22: 12 | AG22: =AF22*Y22 -> 43795454 | AH22: =AC22+AG22 -> 2.7737121e+08 | AI22: =O22-AH22 -> 72992424 | AJ22: =+AE22-AF22 -> 20 | AK22: 12 | AL22: =AK22*Y22 -> 43795454 | AM22: =AH22+AL22 -> 3.2116667e+08 | AN22: =O22-AM22 -> 29196970 | AO22: =+AJ22-AK22 -> 8 | AP22: 8 | AQ22: =AP22*Y22 -> 29196970 | AR22: =AM22+AQ22 -> 3.5036364e+08 | AS22: =O22-AR22 -> 0 | AT22: =+AO22-AP22 -> 0 | AU22: 0 | AV22: =AU22*AD22 -> 0 | AW22: =AR22+AV22 -> 3.5036364e+08 | AX22: =O22-AW22 -> 0 | AZ22: =SUM(BA22:BL22) -> 0 | BA22: =+Y22*0 -> 0 | BB22: =+Y22*0 -> 0 | BC22: =+Y22*0 -> 0 | BD22: =+Y22*0 -> 0 | BE22: =+Y22*0 -> 0 | BF22: =+Y22*0 -> 0 | BG22: =+Y22*0 -> 0 | BH22: =+Y22*0 -> 0 | BI22: =+Y22*0 -> 0 | BJ22: =+Y22*0 -> 0 | BK22: =+Y22*0 -> 0 | BL22: =+Y22*0 -> 0
C23: 42998 | E23: 1 | F23: Kijang Inova-Assecories Innova | G23: 0.25 | H23: 0.125 | I23: 72919000 | L23: =I23+J23-K23 -> 72919000 | O23: =L23+M23-N23 -> 72919000 | P23: =100%/G23 -> 4 | Q23: =P23*12 -> 48 | R23: =100%/H23 -> 8 | S23: =R23*12 -> 96 | T23: =MONTH(C23) -> 9 | U23: =YEAR(C23) -> 2017 | V23: =IF(T23=1, 12, T23-1) -> 8 | W23: =IF(T23=1,U23+R23-1,U23+R23) -> 2025 | X23: 0 | Y23: =L23/S23 -> 759572.92 | Z23: 44 | AA23: 12 | AB23: =AA23*Y23 -> 9114875 | AC23: 48612667 | AD23: =O23-AC23 -> 24306333 | AE23: =+Z23-AA23 -> 32 | AF23: 12 | AG23: =AF23*Y23 -> 9114875 | AH23: =AC23+AG23 -> 57727542 | AI23: =O23-AH23 -> 15191458 | AJ23: =+AE23-AF23 -> 20 | AK23: 12 | AL23: =AK23*Y23 -> 9114875 | AM23: =AH23+AL23 -> 66842417 | AN23: =O23-AM23 -> 6076583.3 | AO23: =+AJ23-AK23 -> 8 | AP23: 8 | AQ23: =AP23*Y23 -> 6076583.3 | AR23: =AM23+AQ23 -> 72919000 | AS23: =O23-AR23 -> 0 | AT23: =+AO23-AP23 -> 0 | AU23: 0 | AV23: =AU23*AD23 -> 0 | AW23: =AR23+AV23 -> 72919000 | AX23: =O23-AW23 -> 0 | AZ23: =SUM(BA23:BL23) -> 0 | BA23: =+Y23*0 -> 0 | BB23: =+Y23*0 -> 0 | BC23: =+Y23*0 -> 0 | BD23: =+Y23*0 -> 0 | BE23: =+Y23*0 -> 0 | BF23: =+Y23*0 -> 0 | BG23: =+Y23*0 -> 0 | BH23: =+Y23*0 -> 0 | BI23: =+Y23*0 -> 0 | BJ23: =+Y23*0 -> 0 | BK23: =+Y23*0 -> 0 | BL23: =+Y23*0 -> 0
C24: 43026 | E24: 1 | F24: Mobil Proton Exora Thn2009 | G24: 0.25 | H24: 0.125 | I24: 60000000 | L24: =I24+J24-K24 -> 60000000 | O24: =L24+M24-N24 -> 60000000 | P24: =100%/G24 -> 4 | Q24: =P24*12 -> 48 | R24: =100%/H24 -> 8 | S24: =R24*12 -> 96 | T24: =MONTH(C24) -> 10 | U24: =YEAR(C24) -> 2017 | V24: =IF(T24=1, 12, T24-1) -> 9 | W24: =IF(T24=1,U24+R24-1,U24+R24) -> 2025 | X24: 0 | Y24: =L24/S24 -> 625000 | Z24: 45 | AA24: 12 | AB24: =AA24*Y24 -> 7500000 | AC24: 39375000 | AD24: =O24-AC24 -> 20625000 | AE24: =+Z24-AA24 -> 33 | AF24: 12 | AG24: =AF24*Y24 -> 7500000 | AH24: =AC24+AG24 -> 46875000 | AI24: =O24-AH24 -> 13125000 | AJ24: =+AE24-AF24 -> 21 | AK24: 12 | AL24: =AK24*Y24 -> 7500000 | AM24: =AH24+AL24 -> 54375000 | AN24: =O24-AM24 -> 5625000 | AO24: =+AJ24-AK24 -> 9 | AP24: 9 | AQ24: =AP24*Y24 -> 5625000 | AR24: =AM24+AQ24 -> 60000000 | AS24: =O24-AR24 -> 0 | AT24: =+AO24-AP24 -> 0 | AU24: 0 | AV24: =AU24*AD24 -> 0 | AW24: =AR24+AV24 -> 60000000 | AX24: =O24-AW24 -> 0 | AZ24: =SUM(BA24:BL24) -> 0 | BA24: =+Y24*0 -> 0 | BB24: =+Y24*0 -> 0 | BC24: =+Y24*0 -> 0 | BD24: =+Y24*0 -> 0 | BE24: =+Y24*0 -> 0 | BF24: =+Y24*0 -> 0 | BG24: =+Y24*0 -> 0 | BH24: =+Y24*0 -> 0 | BI24: =+Y24*0 -> 0 | BJ24: =+Y24*0 -> 0 | BK24: =+Y24*0 -> 0 | BL24: =+Y24*0 -> 0
C25: 43046 | E25: 1 | F25: Mobil Toyota Innova G 2009 | G25: 0.25 | H25: 0.125 | I25: 135000000 | L25: =I25+J25-K25 -> 135000000 | O25: =L25+M25-N25 -> 135000000 | P25: =100%/G25 -> 4 | Q25: =P25*12 -> 48 | R25: =100%/H25 -> 8 | S25: =R25*12 -> 96 | T25: =MONTH(C25) -> 11 | U25: =YEAR(C25) -> 2017 | V25: =IF(T25=1, 12, T25-1) -> 10 | W25: =IF(T25=1,U25+R25-1,U25+R25) -> 2025 | X25: 0 | Y25: =L25/S25 -> 1406250 | Z25: 46 | AA25: 12 | AB25: =AA25*Y25 -> 16875000 | AC25: 87187500 | AD25: =O25-AC25 -> 47812500 | AE25: =+Z25-AA25 -> 34 | AF25: 12 | AG25: =AF25*Y25 -> 16875000 | AH25: =AC25+AG25 -> 104062500 | AI25: =O25-AH25 -> 30937500 | AJ25: =+AE25-AF25 -> 22 | AK25: 12 | AL25: =AK25*Y25 -> 16875000 | AM25: =AH25+AL25 -> 120937500 | AN25: =O25-AM25 -> 14062500 | AO25: =+AJ25-AK25 -> 10 | AP25: 10 | AQ25: =AP25*Y25 -> 14062500 | AR25: =AM25+AQ25 -> 135000000 | AS25: =O25-AR25 -> 0 | AT25: =+AO25-AP25 -> 0 | AU25: 0 | AV25: =AU25*AD25 -> 0 | AW25: =AR25+AV25 -> 135000000 | AX25: =O25-AW25 -> 0 | AZ25: =SUM(BA25:BL25) -> 0 | BA25: =+Y25*0 -> 0 | BB25: =+Y25*0 -> 0 | BC25: =+Y25*0 -> 0 | BD25: =+Y25*0 -> 0 | BE25: =+Y25*0 -> 0 | BF25: =+Y25*0 -> 0 | BG25: =+Y25*0 -> 0 | BH25: =+Y25*0 -> 0 | BI25: =+Y25*0 -> 0 | BJ25: =+Y25*0 -> 0 | BK25: =+Y25*0 -> 0 | BL25: =+Y25*0 -> 0
C26: 43143 | E26: 1 | F26: Motor Honda Vario Black | G26: 0.25 | H26: 0.125 | J26: 21400000 | L26: =I26+J26-K26 -> 21400000 | O26: =L26+M26-N26 -> 21400000 | P26: =100%/G26 -> 4 | Q26: =P26*12 -> 48 | R26: =100%/H26 -> 8 | S26: =R26*12 -> 96 | T26: =MONTH(C26) -> 2 | U26: =YEAR(C26) -> 2018 | V26: =IF(T26=1, 12, T26-1) -> 1 | W26: =IF(T26=1,U26+R26-1,U26+R26) -> 2026 | Y26: =L26/S26 -> 222916.67 | Z26: 49 | AA26: 12 | AB26: =AA26*Y26 -> 2675000 | AC26: 13152083 | AD26: =O26-AC26 -> 8247916.7 | AE26: =+Z26-AA26 -> 37 | AF26: 12 | AG26: =AF26*Y26 -> 2675000 | AH26: =AC26+AG26 -> 15827083 | AI26: =O26-AH26 -> 5572916.7 | AJ26: =+AE26-AF26 -> 25 | AK26: 12 | AL26: =AK26*Y26 -> 2675000 | AM26: =AH26+AL26 -> 18502083 | AN26: =O26-AM26 -> 2897916.7 | AO26: =+AJ26-AK26 -> 13 | AP26: 12 | AQ26: =AP26*Y26 -> 2675000 | AR26: =AM26+AQ26 -> 21177083 | AS26: =O26-AR26 -> 222916.67 | AT26: =+AO26-AP26 -> 1 | AU26: 1 | AV26: =AU26*Y26 -> 222916.67 | AW26: =AR26+AV26 -> 21400000 | AX26: =O26-AW26 -> 0 | AZ26: =SUM(BA26:BL26) -> 222916.67 | BA26: =+Y26*1 -> 222916.67 | BB26: =+Y26*0 -> 0 | BC26: =+Y26*0 -> 0 | BD26: =+Y26*0 -> 0 | BE26: =+Y26*0 -> 0 | BF26: =+Y26*0 -> 0 | BG26: =+Y26*0 -> 0 | BH26: =+Y26*0 -> 0 | BI26: =+Y26*0 -> 0 | BJ26: =+Y26*0 -> 0 | BK26: =+Y26*0 -> 0 | BL26: =+Y26*0 -> 0
C27: 43353 | E27: 1 | F27: Motor N-MAX | G27: 0.25 | H27: 0.125 | J27: 27000000 | L27: =I27+J27-K27 -> 27000000 | O27: =L27+M27-N27 -> 27000000 | P27: =100%/G27 -> 4 | Q27: =P27*12 -> 48 | R27: =100%/H27 -> 8 | S27: =R27*12 -> 96 | T27: =MONTH(C27) -> 9 | U27: =YEAR(C27) -> 2018 | V27: =IF(T27=1, 12, T27-1) -> 8 | W27: =IF(T27=1,U27+R27-1,U27+R27) -> 2026 | Y27: =L27/S27 -> 281250 | Z27: 56 | AA27: 12 | AB27: =AA27*Y27 -> 3375000 | AC27: 14625000 | AD27: =O27-AC27 -> 12375000 | AE27: =+Z27-AA27 -> 44 | AF27: 12 | AG27: =AF27*Y27 -> 3375000 | AH27: =AC27+AG27 -> 18000000 | AI27: =O27-AH27 -> 9000000 | AJ27: =+AE27-AF27 -> 32 | AK27: 12 | AL27: =AK27*Y27 -> 3375000 | AM27: =AH27+AL27 -> 21375000 | AN27: =O27-AM27 -> 5625000 | AO27: =+AJ27-AK27 -> 20 | AP27: 12 | AQ27: =AP27*Y27 -> 3375000 | AR27: =AM27+AQ27 -> 24750000 | AS27: =O27-AR27 -> 2250000 | AT27: =+AO27-AP27 -> 8 | AU27: 8 | AV27: =AU27*Y27 -> 2250000 | AW27: =AR27+AV27 -> 27000000 | AX27: =O27-AW27 -> 0 | AZ27: =SUM(BA27:BL27) -> 2250000 | BA27: =+Y27*1 -> 281250 | BB27: =+Y27*1 -> 281250 | BC27: =+Y27*1 -> 281250 | BD27: =+Y27*1 -> 281250 | BE27: =+Y27*1 -> 281250 | BF27: =+Y27*1 -> 281250 | BG27: =+Y27*1 -> 281250 | BH27: =+Y27*1 -> 281250 | BI27: =+Y27*0 -> 0 | BJ27: =+Y27*0 -> 0 | BK27: =+Y27*0 -> 0 | BL27: =+Y27*0 -> 0
C29: 44773 | E29: 1 | F29: Mobil Toyota Camry A/T 2015 | G29: 0.125 | H29: 0.125 | L29: 240000000 | O29: =+L29 -> 240000000 | R29: =100%/H29 -> 8 | S29: =R29*12 -> 96 | T29: =MONTH(C29) -> 7 | U29: =YEAR(C29) -> 2022 | V29: =IF(T29=1, 12, T29-1) -> 6 | W29: =IF(T29=1,U29+R29-1,U29+R29) -> 2030 | Y29: =L29/S29 -> 2500000 | Z29: 90 | AA29: 6 | AB29: =AA29*Y29 -> 15000000 | AC29: 15000000 | AD29: =L29-AC29 -> 225000000 | AE29: =+Z29-AA29 -> 84 | AF29: 12 | AG29: =AF29*Y29 -> 30000000 | AH29: =AC29+AG29 -> 45000000 | AI29: =O29-AH29 -> 195000000 | AJ29: =+AE29-AF29 -> 72 | AK29: 12 | AL29: =AK29*Y29 -> 30000000 | AM29: =AH29+AL29 -> 75000000 | AN29: =O29-AM29 -> 165000000 | AO29: =+AJ29-AK29 -> 60 | AP29: 7 | AQ29: =AP29*Y29 -> 17500000 | AR29: =AM29+AQ29 -> 92500000 | AS29: =O29-AR29 -> 147500000 | AT29: 0 | AU29: 0 | AV29: =AU29*AD29 -> 0 | AW29: 0 | AX29: 0 | AZ29: =SUM(BA29:BL29) -> 0 | BA29: =+Y29*0 -> 0 | BB29: =+Y29*0 -> 0 | BC29: =+Y29*0 -> 0 | BD29: =+Y29*0 -> 0 | BE29: =+Y29*0 -> 0 | BF29: =+Y29*0 -> 0 | BG29: =+Y29*0 -> 0 | BH29: =+Y29*0 -> 0 | BI29: =+Y29*0 -> 0 | BJ29: =+Y29*0 -> 0 | BK29: =+Y29*0 -> 0 | BL29: =+Y29*0 -> 0
C30: 44837 | E30: 2 | F30: Mobil Mitsubishi Expander Ultimate | G30: 0.125 | H30: 0.125 | L30: 525798600 | O30: =+L30 -> 525798600 | R30: =100%/H30 -> 8 | S30: =R30*12 -> 96 | T30: =MONTH(C30) -> 10 | U30: =YEAR(C30) -> 2022 | V30: =IF(T30=1, 12, T30-1) -> 9 | W30: =IF(T30=1,U30+R30-1,U30+R30) -> 2030 | Y30: =L30/S30 -> 5477068.8 | Z30: 93 | AA30: 3 | AB30: =AA30*Y30 -> 16431206 | AC30: 16431206 | AD30: =L30-AC30 -> 5.0936739e+08 | AE30: =+Z30-AA30 -> 90 | AF30: 12 | AG30: =AF30*Y30 -> 65724825 | AH30: =AC30+AG30 -> 82156031 | AI30: =O30-AH30 -> 4.4364257e+08 | AJ30: =+AE30-AF30 -> 78 | AK30: 12 | AL30: =AK30*Y30 -> 65724825 | AM30: =AH30+AL30 -> 1.4788086e+08 | AN30: =O30-AM30 -> 3.7791774e+08 | AO30: =+AJ30-AK30 -> 66 | AP30: 12 | AQ30: =AP30*Y30 -> 65724825 | AR30: =AM30+AQ30 -> 2.1360568e+08 | AS30: =O30-AR30 -> 3.1219292e+08 | AT30: =+AO30-AP30 -> 54 | AU30: 12 | AV30: =AU30*Y30 -> 65724825 | AW30: =AR30+AV30 -> 2.7933051e+08 | AX30: =O30-AW30 -> 2.4646809e+08 | AZ30: =SUM(BA30:BL30) -> 65724825 | BA30: =+Y30*1 -> 5477068.8 | BB30: =+Y30*1 -> 5477068.8 | BC30: =+Y30*1 -> 5477068.8 | BD30: =+Y30*1 -> 5477068.8 | BE30: =+Y30*1 -> 5477068.8 | BF30: =+Y30*1 -> 5477068.8 | BG30: =+Y30*1 -> 5477068.8 | BH30: =+Y30*1 -> 5477068.8 | BI30: =+Y30*1 -> 5477068.8 | BJ30: =+Y30*1 -> 5477068.8 | BK30: =+Y30*1 -> 5477068.8 | BL30: =+Y30*1 -> 5477068.8
C31: 44868 | E31: 2 | F31: Mobil Mitsubishi Expander Ultimate | G31: 0.125 | H31: 0.125 | L31: 525798600 | O31: =+L31 -> 525798600 | R31: =100%/H31 -> 8 | S31: =R31*12 -> 96 | T31: =MONTH(C31) -> 11 | U31: =YEAR(C31) -> 2022 | V31: =IF(T31=1, 12, T31-1) -> 10 | W31: =IF(T31=1,U31+R31-1,U31+R31) -> 2030 | Y31: =L31/S31 -> 5477068.8 | Z31: 94 | AA31: 2 | AB31: =AA31*Y31 -> 10954138 | AC31: 10954138 | AD31: =L31-AC31 -> 5.1484446e+08 | AE31: =+Z31-AA31 -> 92 | AF31: 12 | AG31: =AF31*Y31 -> 65724825 | AH31: =AC31+AG31 -> 76678962 | AI31: =O31-AH31 -> 4.4911964e+08 | AJ31: =+AE31-AF31 -> 80 | AK31: 12 | AL31: =AK31*Y31 -> 65724825 | AM31: =AH31+AL31 -> 1.4240379e+08 | AN31: =O31-AM31 -> 3.8339481e+08 | AO31: =+AJ31-AK31 -> 68 | AP31: 12 | AQ31: =AP31*Y31 -> 65724825 | AR31: =AM31+AQ31 -> 2.0812861e+08 | AS31: =O31-AR31 -> 3.1766999e+08 | AT31: =+AO31-AP31 -> 56 | AU31: 12 | AV31: =AU31*Y31 -> 65724825 | AW31: =AR31+AV31 -> 2.7385344e+08 | AX31: =O31-AW31 -> 2.5194516e+08 | AZ31: =SUM(BA31:BL31) -> 65724825 | BA31: =+Y31*1 -> 5477068.8 | BB31: =+Y31*1 -> 5477068.8 | BC31: =+Y31*1 -> 5477068.8 | BD31: =+Y31*1 -> 5477068.8 | BE31: =+Y31*1 -> 5477068.8 | BF31: =+Y31*1 -> 5477068.8 | BG31: =+Y31*1 -> 5477068.8 | BH31: =+Y31*1 -> 5477068.8 | BI31: =+Y31*1 -> 5477068.8 | BJ31: =+Y31*1 -> 5477068.8 | BK31: =+Y31*1 -> 5477068.8 | BL31: =+Y31*1 -> 5477068.8
C32: 44917 | E32: 3 | F32: Mobil Mitsubishi Expander Ultimate | G32: 0.125 | H32: 0.125 | L32: 788697900 | O32: =+L32 -> 788697900 | R32: =100%/H32 -> 8 | S32: =R32*12 -> 96 | T32: =MONTH(C32) -> 12 | U32: =YEAR(C32) -> 2022 | V32: =IF(T32=1, 12, T32-1) -> 11 | W32: =IF(T32=1,U32+R32-1,U32+R32) -> 2030 | Y32: =L32/S32 -> 8215603.1 | Z32: 95 | AA32: 1 | AB32: =AA32*Y32 -> 8215603.1 | AC32: 8215603.1 | AD32: =L32-AC32 -> 7.804823e+08 | AE32: =+Z32-AA32 -> 94 | AF32: 12 | AG32: =AF32*Y32 -> 98587238 | AH32: =AC32+AG32 -> 1.0680284e+08 | AI32: =O32-AH32 -> 6.8189506e+08 | AJ32: =+AE32-AF32 -> 82 | AK32: 12 | AL32: =AK32*Y32 -> 98587238 | AM32: =AH32+AL32 -> 2.0539008e+08 | AN32: =O32-AM32 -> 5.8330782e+08 | AO32: =+AJ32-AK32 -> 70 | AP32: 12 | AQ32: =AP32*Y32 -> 98587238 | AR32: =AM32+AQ32 -> 3.0397732e+08 | AS32: =O32-AR32 -> 4.8472058e+08 | AT32: =+AO32-AP32 -> 58 | AU32: 12 | AV32: =AU32*Y32 -> 98587238 | AW32: =AR32+AV32 -> 4.0256455e+08 | AX32: =O32-AW32 -> 3.8613335e+08 | AZ32: =SUM(BA32:BL32) -> 98587238 | BA32: =+Y32*1 -> 8215603.1 | BB32: =+Y32*1 -> 8215603.1 | BC32: =+Y32*1 -> 8215603.1 | BD32: =+Y32*1 -> 8215603.1 | BE32: =+Y32*1 -> 8215603.1 | BF32: =+Y32*1 -> 8215603.1 | BG32: =+Y32*1 -> 8215603.1 | BH32: =+Y32*1 -> 8215603.1 | BI32: =+Y32*1 -> 8215603.1 | BJ32: =+Y32*1 -> 8215603.1 | BK32: =+Y32*1 -> 8215603.1 | BL32: =+Y32*1 -> 8215603.1
L35: =SUM(L12:L33) -> 4099100297 | O35: =SUM(O12:O33) -> 4099100297 | AB35: =SUM(AB12:AB33) -> 1.9637133e+08 | AC35: =SUM(AC12:AC33) -> 1.707033e+09 | AD35: =SUM(AD12:AD33) -> 2.3920673e+09 | AG35: =SUM(AG12:AG33) -> 4.0580728e+08 | AH35: =SUM(AH12:AH33) -> 2.1128403e+09 | AI35: =SUM(AI12:AI33) -> 1.98626e+09 | AL35: =SUM(AL12:AL33) -> 4.0249551e+08 | AM35: =SUM(AM12:AM33) -> 2.5153358e+09 | AN35: =SUM(AN12:AN33) -> 1.5837645e+09 | AQ35: =SUM(AQ12:AQ33) -> 3.1920813e+08 | AR35: =SUM(AR12:AR33) -> 2.2878494e+09 | AS35: =SUM(AS12:AS33) -> 1.2645564e+09 | AV35: =SUM(AV12:AV33) -> 2.325098e+08 | AW35: =SUM(AW12:AW33) -> 2.4278593e+09 | AX35: =SUM(AX12:AX33) -> 8.845466e+08 | AZ35: =SUM(AZ12:AZ33) -> 2.325098e+08 | BA35: =SUM(BA12:BA33) -> 19673907 | BB35: =SUM(BB12:BB33) -> 19450991 | BC35: =SUM(BC12:BC33) -> 19450991 | BD35: =SUM(BD12:BD33) -> 19450991 | BE35: =SUM(BE12:BE33) -> 19450991 | BF35: =SUM(BF12:BF33) -> 19450991 | BG35: =SUM(BG12:BG33) -> 19450991 | ... BL35: =SUM(BL12:BL33) -> 19169741
C37: 45463 | E37: 1 | F37: Motor Yamaha PCX 150CBS | G37: 0.125 | H37: 0.125 | L37: 30192399 | O37: =+L37 -> 30192399 | R37: =100%/H37 -> 8 | S37: =R37*12 -> 96 | T37: =MONTH(C37) -> 6 | U37: =YEAR(C37) -> 2024 | V37: =IF(T37=1, 12, T37-1) -> 5 | W37: =IF(T37=1,U37+R37-1,U37+R37) -> 2032 | Y37: =L37/S37 -> 314504.16 | Z37: 96 | AE37: 96 | AJ37: =+AE37-AF37 -> 96 | AK37: 7 | AL37: =AK37*Y37 -> 2201529.1 | AM37: =AH37+AL37 -> 2201529.1 | AN37: =O37-AM37 -> 27990870 | AO37: =+AJ37-AK37 -> 89 | AP37: 12 | AQ37: =AP37*Y37 -> 3774049.9 | AR37: =AM37+AQ37 -> 5975579 | AS37: =O37-AR37 -> 24216820 | AT37: =+AO37-AP37 -> 77 | AU37: 12 | AV37: =AU37*Y37 -> 3774049.9 | AW37: =AR37+AV37 -> 9749628.8 | AX37: =O37-AW37 -> 20442770 | AZ37: =SUM(BA37:BL37) -> 3774049.9 | BA37: =+Y37*1 -> 314504.16 | BB37: =+Y37*1 -> 314504.16 | BC37: =+Y37*1 -> 314504.16 | BD37: =+Y37*1 -> 314504.16 | BE37: =+Y37*1 -> 314504.16 | BF37: =+Y37*1 -> 314504.16 | BG37: =+Y37*1 -> 314504.16 | BH37: =+Y37*1 -> 314504.16 | BI37: =+Y37*1 -> 314504.16 | BJ37: =+Y37*1 -> 314504.16 | BK37: =+Y37*1 -> 314504.16 | BL37: =+Y37*1 -> 314504.16
C38: 45642 | E38: 1 | F38: Mobil Toyota Innova Zenix 2.0 Q HV CVT | G38: 0.125 | H38: 0.125 | L38: 612142766 | O38: =+L38 -> 612142766 | R38: =100%/H38 -> 8 | S38: =R38*12 -> 96 | T38: =MONTH(C38) -> 12 | U38: =YEAR(C38) -> 2024 | V38: =IF(T38=1, 12, T38-1) -> 11 | W38: =IF(T38=1,U38+R38-1,U38+R38) -> 2032 | Y38: =L38/S38 -> 6376487.1 | Z38: 96 | AE38: 96 | AJ38: =+AE38-AF38 -> 96 | AK38: 1 | AL38: =AK38*Y38 -> 6376487.1 | AM38: =AH38+AL38 -> 6376487.1 | AN38: =O38-AM38 -> 6.0576628e+08 | AO38: =+AJ38-AK38 -> 95 | AP38: 12 | AQ38: =AP38*Y38 -> 76517846 | AR38: =AM38+AQ38 -> 82894333 | AS38: =O38-AR38 -> 5.2924843e+08 | AT38: =+AO38-AP38 -> 83 | AU38: 12 | AV38: =AU38*Y38 -> 76517846 | AW38: =AR38+AV38 -> 1.5941218e+08 | AX38: =O38-AW38 -> 4.5273059e+08 | AZ38: =SUM(BA38:BL38) -> 76517846 | BA38: =+Y38*1 -> 6376487.1 | BB38: =+Y38*1 -> 6376487.1 | BC38: =+Y38*1 -> 6376487.1 | BD38: =+Y38*1 -> 6376487.1 | BE38: =+Y38*1 -> 6376487.1 | BF38: =+Y38*1 -> 6376487.1 | BG38: =+Y38*1 -> 6376487.1 | BH38: =+Y38*1 -> 6376487.1 | BI38: =+Y38*1 -> 6376487.1 | BJ38: =+Y38*1 -> 6376487.1 | BK38: =+Y38*1 -> 6376487.1 | BL38: =+Y38*1 -> 6376487.1
C39: 45642 | E39: 1 | F39: Mobil Toyota All New Veloz 1.5 Q CVT | G39: 0.125 | H39: 0.125 | L39: 282760478 | O39: =+L39 -> 282760478 | R39: =100%/H39 -> 8 | S39: =R39*12 -> 96 | T39: =MONTH(C39) -> 12 | U39: =YEAR(C39) -> 2024 | V39: =IF(T39=1, 12, T39-1) -> 11 | W39: =IF(T39=1,U39+R39-1,U39+R39) -> 2032 | Y39: =L39/S39 -> 2945421.6 | Z39: 96 | AE39: 96 | AJ39: =+AE39-AF39 -> 96 | AK39: 1 | AL39: =AK39*Y39 -> 2945421.6 | AM39: =AH39+AL39 -> 2945421.6 | AN39: =O39-AM39 -> 2.7981506e+08 | AO39: =+AJ39-AK39 -> 95 | AP39: 12 | AQ39: =AP39*Y39 -> 35345060 | AR39: =AM39+AQ39 -> 38290481 | AS39: =O39-AR39 -> 2.4447e+08 | AT39: =+AO39-AP39 -> 83 | AU39: 12 | AV39: =AU39*Y39 -> 35345060 | AW39: =AR39+AV39 -> 73635541 | AX39: =O39-AW39 -> 2.0912494e+08 | AZ39: =SUM(BA39:BL39) -> 35345060 | BA39: =+Y39*1 -> 2945421.6 | BB39: =+Y39*1 -> 2945421.6 | BC39: =+Y39*1 -> 2945421.6 | BD39: =+Y39*1 -> 2945421.6 | BE39: =+Y39*1 -> 2945421.6 | BF39: =+Y39*1 -> 2945421.6 | BG39: =+Y39*1 -> 2945421.6 | BH39: =+Y39*1 -> 2945421.6 | BI39: =+Y39*1 -> 2945421.6 | BJ39: =+Y39*1 -> 2945421.6 | BK39: =+Y39*1 -> 2945421.6 | BL39: =+Y39*1 -> 2945421.6
C40: 45642 | E40: 1 | F40: Mobil Daihatsu Grand Max MB 1.5 D PS | G40: 0.125 | H40: 0.125 | L40: 235749638 | O40: =+L40 -> 235749638 | R40: =100%/H40 -> 8 | S40: =R40*12 -> 96 | T40: =MONTH(C40) -> 12 | U40: =YEAR(C40) -> 2024 | V40: =IF(T40=1, 12, T40-1) -> 11 | W40: =IF(T40=1,U40+R40-1,U40+R40) -> 2032 | Y40: =L40/S40 -> 2455725.4 | Z40: 96 | AE40: 96 | AJ40: =+AE40-AF40 -> 96 | AK40: 1 | AL40: =AK40*Y40 -> 2455725.4 | AM40: =AH40+AL40 -> 2455725.4 | AN40: =O40-AM40 -> 2.3329391e+08 | AO40: =+AJ40-AK40 -> 95 | AP40: 12 | AQ40: =AP40*Y40 -> 29468705 | AR40: =AM40+AQ40 -> 31924430 | AS40: =O40-AR40 -> 2.0382521e+08 | AT40: =+AO40-AP40 -> 83 | AU40: 12 | AV40: =AU40*Y40 -> 29468705 | AW40: =AR40+AV40 -> 61393135 | AX40: =O40-AW40 -> 1.743565e+08 | AZ40: =SUM(BA40:BL40) -> 29468705 | BA40: =+Y40*1 -> 2455725.4 | BB40: =+Y40*1 -> 2455725.4 | BC40: =+Y40*1 -> 2455725.4 | BD40: =+Y40*1 -> 2455725.4 | BE40: =+Y40*1 -> 2455725.4 | BF40: =+Y40*1 -> 2455725.4 | BG40: =+Y40*1 -> 2455725.4 | BH40: =+Y40*1 -> 2455725.4 | BI40: =+Y40*1 -> 2455725.4 | BJ40: =+Y40*1 -> 2455725.4 | BK40: =+Y40*1 -> 2455725.4 | BL40: =+Y40*1 -> 2455725.4
L42: =SUM(L37:L41) -> 1160845281 | O42: =SUM(O37:O41) -> 1160845281 | AL42: =SUM(AL37:AL41) -> 13979163 | AM42: =SUM(AM37:AM41) -> 13979163 | AN42: =SUM(AN37:AN41) -> 1.1468661e+09 | AQ42: =SUM(AQ37:AQ41) -> 1.4510566e+08 | AR42: =SUM(AR37:AR41) -> 1.5908482e+08 | AS42: =SUM(AS37:AS41) -> 1.0017605e+09 | AV42: =SUM(AV37:AV41) -> 1.4510566e+08 | AW42: =SUM(AW37:AW41) -> 3.0419048e+08 | AX42: =SUM(AX37:AX41) -> 8.566548e+08 | AZ42: =SUM(AZ37:AZ41) -> 1.4510566e+08 | BA42: =SUM(BA37:BA41) -> 12092138 | BB42: =SUM(BB37:BB41) -> 12092138 | BC42: =SUM(BC37:BC41) -> 12092138 | BD42: =SUM(BD37:BD41) -> 12092138 | BE42: =SUM(BE37:BE41) -> 12092138 | BF42: =SUM(BF37:BF41) -> 12092138 | BG42: =SUM(BG37:BG41) -> 12092138 | ... BL42: =SUM(BL37:BL41) -> 12092138
C44: 45799 | E44: 1 | F44: Motor Honda Vario 160ABS | G44: 0.125 | H44: 0.125 | L44: 28671531 | O44: =+L44 -> 28671531 | R44: =100%/H44 -> 8 | S44: =R44*12 -> 96 | T44: =MONTH(C44) -> 5 | U44: =YEAR(C44) -> 2025 | V44: =IF(T44=1, 12, T44-1) -> 4 | W44: =IF(T44=1,U44+R44-1,U44+R44) -> 2033 | Y44: =L44/S44 -> 298661.78 | Z44: 96 | AE44: 96 | AJ44: =+AE44-AF44 -> 96 | AO44: =+AJ44-AK44 -> 96 | AP44: 8 | AQ44: =AP44*Y44 -> 2389294.2 | AR44: =AM44+AQ44 -> 2389294.2 | AS44: =O44-AR44 -> 26282237 | AT44: =+AO44-AP44 -> 88 | AU44: 12 | AV44: =AU44*Y44 -> 3583941.4 | AW44: =AR44+AV44 -> 5973235.6 | AX44: =O44-AW44 -> 22698295 | AZ44: =SUM(BA44:BL44) -> 3583941.4 | BA44: =+Y44*1 -> 298661.78 | BB44: =+Y44*1 -> 298661.78 | BC44: =+Y44*1 -> 298661.78 | BD44: =+Y44*1 -> 298661.78 | BE44: =+Y44*1 -> 298661.78 | BF44: =+Y44*1 -> 298661.78 | BG44: =+Y44*1 -> 298661.78 | BH44: =+Y44*1 -> 298661.78 | BI44: =+Y44*1 -> 298661.78 | BJ44: =+Y44*1 -> 298661.78 | BK44: =+Y44*1 -> 298661.78 | BL44: =+Y44*1 -> 298661.78
C45: 45883 | E45: 1 | F45: Mobil JAECOO-J7-SHS | G45: 0.125 | H45: 0.125 | L45: 463126809 | O45: =+L45 -> 463126809 | R45: =100%/H45 -> 8 | S45: =R45*12 -> 96 | T45: =MONTH(C45) -> 8 | U45: =YEAR(C45) -> 2025 | V45: =IF(T45=1, 12, T45-1) -> 7 | W45: =IF(T45=1,U45+R45-1,U45+R45) -> 2033 | Y45: =L45/S45 -> 4824237.6 | Z45: 96 | AE45: 96 | AJ45: =+AE45-AF45 -> 96 | AO45: =+AJ45-AK45 -> 96 | AP45: 5 | AQ45: =AP45*Y45 -> 24121188 | AR45: =AM45+AQ45 -> 24121188 | AS45: =O45-AR45 -> 4.3900562e+08 | AT45: =+AO45-AP45 -> 91 | AU45: 12 | AV45: =AU45*Y45 -> 57890851 | AW45: =AR45+AV45 -> 82012039 | AX45: =O45-AW45 -> 3.8111477e+08 | AZ45: =SUM(BA45:BL45) -> 57890851 | BA45: =+Y45*1 -> 4824237.6 | BB45: =+Y45*1 -> 4824237.6 | BC45: =+Y45*1 -> 4824237.6 | BD45: =+Y45*1 -> 4824237.6 | BE45: =+Y45*1 -> 4824237.6 | BF45: =+Y45*1 -> 4824237.6 | BG45: =+Y45*1 -> 4824237.6 | BH45: =+Y45*1 -> 4824237.6 | BI45: =+Y45*1 -> 4824237.6 | BJ45: =+Y45*1 -> 4824237.6 | BK45: =+Y45*1 -> 4824237.6 | BL45: =+Y45*1 -> 4824237.6
L47: =SUM(L44:L46) -> 491798340 | O47: =SUM(O44:O46) -> 491798340 | AQ47: =SUM(AQ44:AQ46) -> 26510482 | AR47: =SUM(AR44:AR46) -> 26510482 | AS47: =SUM(AS44:AS46) -> 4.6528786e+08 | AV47: =SUM(AV44:AV46) -> 61474792 | AW47: =SUM(AW44:AW46) -> 87985275 | AX47: =SUM(AX44:AX46) -> 4.0381307e+08 | AZ47: =SUM(AZ44:AZ46) -> 61474792 | BA47: =SUM(BA44:BA46) -> 5122899.4 | BB47: =SUM(BB44:BB46) -> 5122899.4 | BC47: =SUM(BC44:BC46) -> 5122899.4 | BD47: =SUM(BD44:BD46) -> 5122899.4 | BE47: =SUM(BE44:BE46) -> 5122899.4 | BF47: =SUM(BF44:BF46) -> 5122899.4 | BG47: =SUM(BG44:BG46) -> 5122899.4 | ... BL47: =SUM(BL44:BL46) -> 5122899.4
L50: =+L35+L42+L47 -> 5751743918 | AL50: =+AL35+AL42 -> 4.1647467e+08 | AM50: =+AM35+AM42 -> 2.5293149e+09 | AN50: =+AN35+AN42 -> 2.7306307e+09 | AQ50: =+AQ35+AQ42+AQ47 -> 4.9082427e+08 | AR50: =+AR35+AR42+AR47 -> 2.4734448e+09 | AS50: =+AS35+AS42+AS47 -> 2.7316047e+09 | AV50: =+AV35+AV42+AV47 -> 4.3909026e+08 | AW50: =+AW35+AW42+AW47 -> 2.820035e+09 | AX50: =+AX35+AX42+AX47 -> 2.1450145e+09 | AZ50: =+AZ35+AZ42+AZ47 -> 4.3909026e+08 | BA50: =+BA35+BA42+BA47 -> 36888945 | BB50: =+BB35+BB42+BB47 -> 36666028 | BC50: =+BC35+BC42+BC47 -> 36666028 | BD50: =+BD35+BD42+BD47 -> 36666028 | BE50: =+BE35+BE42+BE47 -> 36666028 | BF50: =+BF35+BF42+BF47 -> 36666028 | BG50: =+BG35+BG42+BG47 -> 36666028 | ... BL50: =+BL35+BL42+BL47 -> 36384778
E54: ASET TA
C55: 39520 | D55: 42733 | E55: Toyota Kijang Inova B 2203 SY | H55: 0.125 | I55: 245194040 | L55: =I55+J55-K55 -> 245194040 | O55: =L55+M55-N55 -> 245194040 | R55: =100%/H55 -> 8 | S55: =R55*12 -> 96 | T55: =MONTH(D55) -> 12 | U55: =YEAR(D55) -> 2016 | V55: =IF(T55=1, 12, T55-1) -> 11 | W55: =IF(T55=1,U55+R55-1,U55+R55) -> 2024 | Y55: =L55/S55 -> 2554104.6 | Z55: 35 | AA55: 11 | AB55: =AA55*Y55 -> 28095150 | AC55: 1.8134143e+08 | AD55: =O55-AC55 -> 63852615 | AZ55: =SUM(BA55:BL55) -> 0 | BA55: =+Y55*0 -> 0 | BB55: =+Y55*0 -> 0 | BC55: =+Y55*0 -> 0 | BD55: =+Y55*0 -> 0 | BE55: =+Y55*0 -> 0 | BF55: =+Y55*0 -> 0 | BG55: =+Y55*0 -> 0 | BH55: =+Y55*0 -> 0 | BI55: =+Y55*0 -> 0 | BJ55: =+Y55*0 -> 0 | BK55: =+Y55*0 -> 0 | BL55: =+Y55*0 -> 0
C56: 40522 | D56: 42733 | E56: Isuzu Elf NKR 55 95 B 9147 KDA | H56: 0.125 | I56: 258015000 | L56: =I56+J56-K56 -> 258015000 | O56: =L56+M56-N56 -> 258015000 | R56: =100%/H56 -> 8 | S56: =R56*12 -> 96 | T56: =MONTH(D56) -> 12 | U56: =YEAR(D56) -> 2016 | V56: =IF(T56=1, 12, T56-1) -> 11 | W56: =IF(T56=1,U56+R56-1,U56+R56) -> 2024 | Y56: =L56/S56 -> 2687656.2 | Z56: 35 | AA56: 12 | AB56: =AA56*Y56 -> 32251875 | AC56: 193511250 | AD56: =O56-AC56 -> 64503750 | AE56: =+Z56-AA56 -> 23 | AF56: 12 | AG56: =AF56*Y56 -> 32251875 | AH56: =AC56+AG56 -> 225763125 | AI56: =O56-AH56 -> 32251875 | AJ56: =+AE56-AF56 -> 11 | AK56: 12 | AL56: =AK56*Y56 -> 32251875 | AM56: =AH56+AL56 -> 258015000 | AN56: =O56-AM56 -> 0 | AQ56: =AP56*Y56 -> 0 | AR56: =AM56+AQ56 -> 258015000 | AS56: =O56-AR56 -> 0 | AV56: =AU56*AD56 -> 0 | AW56: =AR56+AV56 -> 258015000 | AX56: =O56-AW56 -> 0 | AZ56: =SUM(BA56:BL56) -> 0 | BA56: =+Y56*0 -> 0 | BB56: =+Y56*0 -> 0 | BC56: =+Y56*0 -> 0 | BD56: =+Y56*0 -> 0 | BE56: =+Y56*0 -> 0 | BF56: =+Y56*0 -> 0 | BG56: =+Y56*0 -> 0 | BH56: =+Y56*0 -> 0 | BI56: =+Y56*0 -> 0 | BJ56: =+Y56*0 -> 0 | BK56: =+Y56*0 -> 0 | BL56: =+Y56*0 -> 0
C57: 40522 | D57: 42733 | E57: Toyota Avanza B.1880 KFV | H57: 0.125 | I57: 180150000 | L57: =I57+J57-K57 -> 180150000 | O57: =L57+M57-N57 -> 180150000 | R57: =100%/H57 -> 8 | S57: =R57*12 -> 96 | T57: =MONTH(D57) -> 12 | U57: =YEAR(D57) -> 2016 | V57: =IF(T57=1, 12, T57-1) -> 11 | W57: =IF(T57=1,U57+R57-1,U57+R57) -> 2024 | Y57: =L57/S57 -> 1876562.5 | Z57: 35 | AA57: 12 | AB57: =AA57*Y57 -> 22518750 | AC57: 135112500 | AD57: =O57-AC57 -> 45037500 | AZ57: =SUM(BA57:BL57) -> 0 | BA57: =+Y57*0 -> 0 | BB57: =+Y57*0 -> 0 | BC57: =+Y57*0 -> 0 | BD57: =+Y57*0 -> 0 | BE57: =+Y57*0 -> 0 | BF57: =+Y57*0 -> 0 | BG57: =+Y57*0 -> 0 | BH57: =+Y57*0 -> 0 | BI57: =+Y57*0 -> 0 | BJ57: =+Y57*0 -> 0 | BK57: =+Y57*0 -> 0 | BL57: =+Y57*0 -> 0
...

Sheet Bangunan
B2: Client | E2: : | F2: =#REF! -> #REF!
B3: Period | E3: : | F3: 43830
B4: Schedule | E4: : | F4: Tes Perhitungan Beban Penyusutan Aset Tetap
B6: No | C6: Tanggal Perolehan | E6: Deskripsi | G6: Tarif | H6: Harga Perolehan | L6: PAJE/CAJE/RJE | O6: Life | S6: Beginning of Depreciation | U6: Ending of Depreciation | W6: Penyusutan per Bulan | Y6: 44926 | AD6: 45291 | AI6: 45657 | AN6: 46022 | AS6: 46387
D7: No Voucher | H7: 43100 | I7: Penambahan | J7: Pengurangan | K7: 43465 | L7: Dr | M7: Cr | N7: =K7 -> 43465 | O7: Awal | Q7: Penyesuaian | S7: Month | T7: Year | U7: Month | V7: Year | Y7: Bulan | AA7: Beban Penyusutan | AB7: Akumulasi Penyusutan | AC7: Nilai Buku | AD7: Bulan | AF7: Beban Penyusutan | AG7: Akumulasi Penyusutan | AH7: Nilai Buku | AI7: Bulan | AK7: Beban Penyusutan | AL7: Akumulasi Penyusutan | AM7: Nilai Buku | AN7: Bulan | AP7: Beban Penyusutan | AQ7: Akumulasi Penyusutan | AR7: Nilai Buku | AS7: Bulan | AU7: Beban Penyusutan | AV7: Akumulasi Penyusutan | AW7: Nilai Buku | AY7: TOTAL | AZ7: JAN | BA7: FEB | BB7: MAR | BC7: APR | BD7: MAY | BE7: JUNE | BF7: JUL | BG7: AUG | BH7: SEP | BI7: OCT | BJ7: NOV | BK7: DEC
K8: Unaudited | N8: Audited | O8: Year | P8: Month | Q8: Year | R8: Month | W8: Awal | X8: Penyesuaian | AY8: 2026
C10: Bangunan
C12: 41722 | E12: Bangunan | G12: 0.1 | H12: 124000000 | K12: =H12+I12-J12 -> 124000000 | N12: =K12+L12-M12 -> 124000000 | O12: 4 | P12: =O12*12 -> 48 | Q12: =100%/G12 -> 10 | R12: =Q12*12 -> 120 | S12: =MONTH(C12) -> 3 | T12: =YEAR(C12) -> 2014 | U12: =IF(S12=1, 12, S12-1) -> 2 | V12: =IF(S12=1,T12+Q12-1,T12+Q12) -> 2024 | W12: =H12/P12 -> 2583333.3 | X12: 420542.64 | Y12: 26 | Z12: 12 | AA12: =Z12*X12 -> 5046511.6 | AB12: 1.181124e+08 | AC12: =N12-AB12 -> 5887596.9 | AD12: =+Y12-Z12 -> 14 | AE12: 12 | AF12: =AE12*X12 -> 5046511.6 | AG12: =+AB12+AF12 -> 1.2315891e+08 | AH12: =N12-AG12 -> 841085.27 | AI12: =+AD12-AE12 -> 2 | AJ12: 2 | AK12: =AJ12*X12 -> 841085.27 | AL12: =+AG12+AK12 -> 1.24e+08 | AM12: =N12-AL12 -> 0 | AN12: =+AI12-AJ12 -> 0 | AO12: 0 | AP12: =AO12*AC12 -> 0 | AQ12: =+AL12+AP12 -> 1.24e+08 | AR12: =N12-AQ12 -> 0 | AS12: =+AN12-AO12 -> 0 | AT12: 0 | AU12: =AT12*AH12 -> 0 | AV12: =+AQ12+AU12 -> 1.24e+08 | AW12: =N12-AV12 -> 0 | AY12: =SUM(AZ12:BK12) -> 0 | AZ12: =+X12*0 -> 0 | BA12: =+X12*0 -> 0 | BB12: =+X12*0 -> 0 | BC12: =+X12*0 -> 0 | BD12: =+X12*0 -> 0 | BE12: =+X12*0 -> 0 | BF12: =+X12*0 -> 0 | BG12: =+X12*0 -> 0 | BH12: =+X12*0 -> 0 | BI12: =+X12*0 -> 0 | BJ12: =+X12*0 -> 0 | BK12: =+X12*0 -> 0
C13: 41750 | E13: Bangunan | G13: 0.1 | H13: 93000000 | K13: =H13+I13-J13 -> 93000000 | N13: =K13+L13-M13 -> 93000000 | O13: 4 | P13: =O13*12 -> 48 | Q13: =100%/G13 -> 10 | R13: =Q13*12 -> 120 | S13: =MONTH(C13) -> 4 | T13: =YEAR(C13) -> 2014 | U13: =IF(S13=1, 12, S13-1) -> 3 | V13: =IF(S13=1,T13+Q13-1,T13+Q13) -> 2024 | W13: =H13/P13 -> 1937500 | X13: 334051.72 | Y13: 27 | Z13: 12 | AA13: =Z13*X13 -> 4008620.7 | AB13: 87989224 | AC13: =N13-AB13 -> 5010775.9 | AD13: =+Y13-Z13 -> 15 | AE13: 12 | AF13: =AE13*X13 -> 4008620.7 | AG13: =+AB13+AF13 -> 91997845 | AH13: =N13-AG13 -> 1002155.2 | AI13: =+AD13-AE13 -> 3 | AJ13: 3 | AK13: =AJ13*X13 -> 1002155.2 | AL13: =+AG13+AK13 -> 93000000 | AM13: =N13-AL13 -> 0 | AN13: =+AI13-AJ13 -> 0 | AO13: 0 | AP13: =AO13*AC13 -> 0 | AQ13: =+AL13+AP13 -> 93000000 | AR13: =N13-AQ13 -> 0 | AS13: =+AN13-AO13 -> 0 | AT13: 0 | AU13: =AT13*AH13 -> 0 | AV13: =+AQ13+AU13 -> 93000000 | AW13: =N13-AV13 -> 0 | AY13: =SUM(AZ13:BK13) -> 0 | AZ13: =+X13*0 -> 0 | BA13: =+X13*0 -> 0 | BB13: =+X13*0 -> 0 | BC13: =+X13*0 -> 0 | BD13: =+X13*0 -> 0 | BE13: =+X13*0 -> 0 | BF13: =+X13*0 -> 0 | BG13: =+X13*0 -> 0 | BH13: =+X13*0 -> 0 | BI13: =+X13*0 -> 0 | BJ13: =+X13*0 -> 0 | BK13: =+X13*0 -> 0
C14: 41817 | E14: Bangunan | G14: 0.1 | H14: 77500000 | K14: =H14+I14-J14 -> 77500000 | N14: =K14+L14-M14 -> 77500000 | O14: 4 | P14: =O14*12 -> 48 | Q14: =100%/G14 -> 10 | R14: =Q14*12 -> 120 | S14: =MONTH(C14) -> 6 | T14: =YEAR(C14) -> 2014 | U14: =IF(S14=1, 12, S14-1) -> 5 | V14: =IF(S14=1,T14+Q14-1,T14+Q14) -> 2024 | W14: =H14/P14 -> 1614583.3 | X14: 308403.56 | Y14: 29 | Z14: 12 | AA14: =Z14*X14 -> 3700842.7 | AB14: 72257140 | AC14: =N14-AB14 -> 5242860.5 | AD14: =+Y14-Z14 -> 17 | AE14: 12 | AF14: =AE14*X14 -> 3700842.7 | AG14: =+AB14+AF14 -> 75957982 | AH14: =N14-AG14 -> 1542017.8 | AI14: =+AD14-AE14 -> 5 | AJ14: 5 | AK14: =AJ14*X14 -> 1542017.8 | AL14: =+AG14+AK14 -> 77500000 | AM14: =N14-AL14 -> 0 | AN14: =+AI14-AJ14 -> 0 | AO14: 0 | AP14: =AO14*AC14 -> 0 | AQ14: =+AL14+AP14 -> 77500000 | AR14: =N14-AQ14 -> 0 | AS14: =+AN14-AO14 -> 0 | AT14: 0 | AU14: =AT14*AH14 -> 0 | AV14: =+AQ14+AU14 -> 77500000 | AW14: =N14-AV14 -> 0 | AY14: =SUM(AZ14:BK14) -> 0 | AZ14: =+X14*0 -> 0 | BA14: =+X14*0 -> 0 | BB14: =+X14*0 -> 0 | BC14: =+X14*0 -> 0 | BD14: =+X14*0 -> 0 | BE14: =+X14*0 -> 0 | BF14: =+X14*0 -> 0 | BG14: =+X14*0 -> 0 | BH14: =+X14*0 -> 0 | BI14: =+X14*0 -> 0 | BJ14: =+X14*0 -> 0 | BK14: =+X14*0 -> 0
C15: 41817 | E15: Bangunan | G15: 0.1 | H15: 39000000 | K15: =H15+I15-J15 -> 39000000 | N15: =K15+L15-M15 -> 39000000 | O15: 4 | P15: =O15*12 -> 48 | Q15: =100%/G15 -> 10 | R15: =Q15*12 -> 120 | S15: =MONTH(C15) -> 6 | T15: =YEAR(C15) -> 2014 | U15: =IF(S15=1, 12, S15-1) -> 5 | V15: =IF(S15=1,T15+Q15-1,T15+Q15) -> 2024 | W15: =H15/P15 -> 812500 | X15: 155196.63 | Y15: 29 | Z15: 12 | AA15: =Z15*X15 -> 1862359.6 | AB15: 36361657 | AC15: =N15-AB15 -> 2638342.7 | AD15: =+Y15-Z15 -> 17 | AE15: 12 | AF15: =AE15*X15 -> 1862359.6 | AG15: =+AB15+AF15 -> 38224017 | AH15: =N15-AG15 -> 775983.15 | AI15: =+AD15-AE15 -> 5 | AJ15: 5 | AK15: =AJ15*X15 -> 775983.15 | AL15: =+AG15+AK15 -> 39000000 | AM15: =N15-AL15 -> 0 | AN15: =+AI15-AJ15 -> 0 | AO15: 0 | AP15: =AO15*AC15 -> 0 | AQ15: =+AL15+AP15 -> 39000000 | AR15: =N15-AQ15 -> 0 | AS15: =+AN15-AO15 -> 0 | AT15: 0 | AU15: =AT15*AH15 -> 0 | AV15: =+AQ15+AU15 -> 39000000 | AW15: =N15-AV15 -> 0 | AY15: =SUM(AZ15:BK15) -> 0 | AZ15: =+X15*0 -> 0 | BA15: =+X15*0 -> 0 | BB15: =+X15*0 -> 0 | BC15: =+X15*0 -> 0 | BD15: =+X15*0 -> 0 | BE15: =+X15*0 -> 0 | BF15: =+X15*0 -> 0 | BG15: =+X15*0 -> 0 | BH15: =+X15*0 -> 0 | BI15: =+X15*0 -> 0 | BJ15: =+X15*0 -> 0 | BK15: =+X15*0 -> 0
C16: 41926 | E16: Bangunan | G16: 0.1 | H16: 40000000 | K16: =H16+I16-J16 -> 40000000 | N16: =K16+L16-M16 -> 40000000 | O16: 4 | P16: =O16*12 -> 48 | Q16: =100%/G16 -> 10 | R16: =Q16*12 -> 120 | S16: =MONTH(C16) -> 10 | T16: =YEAR(C16) -> 2014 | U16: =IF(S16=1, 12, S16-1) -> 9 | V16: =IF(S16=1,T16+Q16-1,T16+Q16) -> 2024 | W16: =H16/P16 -> 833333.33 | X16: 188172.04 | Y16: 33 | Z16: 12 | AA16: =Z16*X16 -> 2258064.5 | AB16: 36048387 | AC16: =N16-AB16 -> 3951612.9 | AD16: =+Y16-Z16 -> 21 | AE16: 12 | AF16: =AE16*X16 -> 2258064.5 | AG16: =+AB16+AF16 -> 38306452 | AH16: =N16-AG16 -> 1693548.4 | AI16: =+AD16-AE16 -> 9 | AJ16: 9 | AK16: =AJ16*X16 -> 1693548.4 | AL16: =+AG16+AK16 -> 40000000 | AM16: =N16-AL16 -> 0 | AN16: =+AI16-AJ16 -> 0 | AO16: 0 | AP16: =AO16*AC16 -> 0 | AQ16: =+AL16+AP16 -> 40000000 | AR16: =N16-AQ16 -> 0 | AS16: =+AN16-AO16 -> 0 | AT16: 0 | AU16: =AT16*AH16 -> 0 | AV16: =+AQ16+AU16 -> 40000000 | AW16: =N16-AV16 -> 0 | AY16: =SUM(AZ16:BK16) -> 0 | AZ16: =+X16*0 -> 0 | BA16: =+X16*0 -> 0 | BB16: =+X16*0 -> 0 | BC16: =+X16*0 -> 0 | BD16: =+X16*0 -> 0 | BE16: =+X16*0 -> 0 | BF16: =+X16*0 -> 0 | BG16: =+X16*0 -> 0 | BH16: =+X16*0 -> 0 | BI16: =+X16*0 -> 0 | BJ16: =+X16*0 -> 0 | BK16: =+X16*0 -> 0
C17: 41934 | E17: Bangunan | G17: 0.1 | H17: 21000000 | K17: =H17+I17-J17 -> 21000000 | N17: =K17+L17-M17 -> 21000000 | O17: 4 | P17: =O17*12 -> 48 | Q17: =100%/G17 -> 10 | R17: =Q17*12 -> 120 | S17: =MONTH(C17) -> 10 | T17: =YEAR(C17) -> 2014 | U17: =IF(S17=1, 12, S17-1) -> 9 | V17: =IF(S17=1,T17+Q17-1,T17+Q17) -> 2024 | W17: =H17/P17 -> 437500 | X17: 98790.323 | Y17: 33 | Z17: 12 | AA17: =Z17*X17 -> 1185483.9 | AB17: 18925403 | AC17: =N17-AB17 -> 2074596.8 | AD17: =+Y17-Z17 -> 21 | AE17: 12 | AF17: =AE17*X17 -> 1185483.9 | AG17: =+AB17+AF17 -> 20110887 | AH17: =N17-AG17 -> 889112.9 | AI17: =+AD17-AE17 -> 9 | AJ17: 9 | AK17: =AJ17*X17 -> 889112.9 | AL17: =+AG17+AK17 -> 21000000 | AM17: =N17-AL17 -> 0 | AN17: =+AI17-AJ17 -> 0 | AO17: 0 | AP17: =AO17*AC17 -> 0 | AQ17: =+AL17+AP17 -> 21000000 | AR17: =N17-AQ17 -> 0 | AS17: =+AN17-AO17 -> 0 | AT17: 0 | AU17: =AT17*AH17 -> 0 | AV17: =+AQ17+AU17 -> 21000000 | AW17: =N17-AV17 -> 0 | AY17: =SUM(AZ17:BK17) -> 0 | AZ17: =+X17*0 -> 0 | BA17: =+X17*0 -> 0 | BB17: =+X17*0 -> 0 | BC17: =+X17*0 -> 0 | BD17: =+X17*0 -> 0 | BE17: =+X17*0 -> 0 | BF17: =+X17*0 -> 0 | BG17: =+X17*0 -> 0 | BH17: =+X17*0 -> 0 | BI17: =+X17*0 -> 0 | BJ17: =+X17*0 -> 0 | BK17: =+X17*0 -> 0
C18: 42010 | E18: Renovasi Gedung Lt.2 | G18: 0.1 | H18: 58000000 | K18: =H18+I18-J18 -> 58000000 | N18: =K18+L18-M18 -> 58000000 | O18: 4 | P18: =O18*12 -> 48 | Q18: =100%/G18 -> 10 | R18: =Q18*12 -> 120 | S18: =MONTH(C18) -> 1 | T18: =YEAR(C18) -> 2015 | U18: =IF(S18=1, 12, S18-1) -> 12 | V18: =IF(S18=1,T18+Q18-1,T18+Q18) -> 2024 | W18: =H18/P18 -> 1208333.3 | X18: 302083.33 | Y18: 36 | Z18: 12 | AA18: =Z18*X18 -> 3625000 | AB18: 50750000 | AC18: =N18-AB18 -> 7250000 | AD18: =+Y18-Z18 -> 24 | AE18: 12 | AF18: =AE18*X18 -> 3625000 | AG18: =+AB18+AF18 -> 54375000 | AH18: =N18-AG18 -> 3625000 | AI18: =+AD18-AE18 -> 12 | AJ18: 12 | AK18: =AJ18*X18 -> 3625000 | AL18: =+AG18+AK18 -> 58000000 | AM18: =N18-AL18 -> 0 | AN18: =+AI18-AJ18 -> 0 | AO18: 0 | AP18: =AO18*AC18 -> 0 | AQ18: =+AL18+AP18 -> 58000000 | AR18: =N18-AQ18 -> 0 | AS18: =+AN18-AO18 -> 0 | AT18: 0 | AU18: =AT18*AH18 -> 0 | AV18: =+AQ18+AU18 -> 58000000 | AW18: =N18-AV18 -> 0 | AY18: =SUM(AZ18:BK18) -> 0 | AZ18: =+X18*0 -> 0 | BA18: =+X18*0 -> 0 | BB18: =+X18*0 -> 0 | BC18: =+X18*0 -> 0 | BD18: =+X18*0 -> 0 | BE18: =+X18*0 -> 0 | BF18: =+X18*0 -> 0 | BG18: =+X18*0 -> 0 | BH18: =+X18*0 -> 0 | BI18: =+X18*0 -> 0 | BJ18: =+X18*0 -> 0 | BK18: =+X18*0 -> 0
C19: 42033 | E19: Renovasi Gedung Lt.2 | G19: 0.1 | H19: 60000000 | K19: =H19+I19-J19 -> 60000000 | N19: =K19+L19-M19 -> 60000000 | O19: 4 | P19: =O19*12 -> 48 | Q19: =100%/G19 -> 10 | R19: =Q19*12 -> 120 | S19: =MONTH(C19) -> 1 | T19: =YEAR(C19) -> 2015 | U19: =IF(S19=1, 12, S19-1) -> 12 | V19: =IF(S19=1,T19+Q19-1,T19+Q19) -> 2024 | W19: =H19/P19 -> 1250000 | X19: 312500 | Y19: 36 | Z19: 12 | AA19: =Z19*X19 -> 3750000 | AB19: 52500000 | AC19: =N19-AB19 -> 7500000 | AD19: =+Y19-Z19 -> 24 | AE19: 12 | AF19: =AE19*X19 -> 3750000 | AG19: =+AB19+AF19 -> 56250000 | AH19: =N19-AG19 -> 3750000 | AI19: =+AD19-AE19 -> 12 | AJ19: 12 | AK19: =AJ19*X19 -> 3750000 | AL19: =+AG19+AK19 -> 60000000 | AM19: =N19-AL19 -> 0 | AN19: =+AI19-AJ19 -> 0 | AO19: 0 | AP19: =AO19*AC19 -> 0 | AQ19: =+AL19+AP19 -> 60000000 | AR19: =N19-AQ19 -> 0 | AS19: =+AN19-AO19 -> 0 | AT19: 0 | AU19: =AT19*AH19 -> 0 | AV19: =+AQ19+AU19 -> 60000000 | AW19: =N19-AV19 -> 0 | AY19: =SUM(AZ19:BK19) -> 0 | AZ19: =+X19*0 -> 0 | BA19: =+X19*0 -> 0 | BB19: =+X19*0 -> 0 | BC19: =+X19*0 -> 0 | BD19: =+X19*0 -> 0 | BE19: =+X19*0 -> 0 | BF19: =+X19*0 -> 0 | BG19: =+X19*0 -> 0 | BH19: =+X19*0 -> 0 | BI19: =+X19*0 -> 0 | BJ19: =+X19*0 -> 0 | BK19: =+X19*0 -> 0
C20: 42102 | E20: Sliding door lt.2 | G20: 0.1 | H20: 9500000 | K20: =H20+I20-J20 -> 9500000 | N20: =K20+L20-M20 -> 9500000 | O20: 4 | P20: =O20*12 -> 48 | Q20: =100%/G20 -> 10 | R20: =Q20*12 -> 120 | S20: =MONTH(C20) -> 4 | T20: =YEAR(C20) -> 2015 | U20: =IF(S20=1, 12, S20-1) -> 3 | V20: =IF(S20=1,T20+Q20-1,T20+Q20) -> 2025 | W20: =H20/P20 -> 197916.67 | X20: 53977.273 | Y20: 39 | Z20: 12 | AA20: =Z20*X20 -> 647727.27 | AB20: 8042613.6 | AC20: =N20-AB20 -> 1457386.4 | AD20: =+Y20-Z20 -> 27 | AE20: 12 | AF20: =AE20*X20 -> 647727.27 | AG20: =+AB20+AF20 -> 8690340.9 | AH20: =N20-AG20 -> 809659.09 | AI20: =+AD20-AE20 -> 15 | AJ20: 12 | AK20: =AJ20*X20 -> 647727.27 | AL20: =+AG20+AK20 -> 9338068.2 | AM20: =N20-AL20 -> 161931.82 | AN20: =+AI20-AJ20 -> 3 | AO20: 3 | AP20: =AO20*X20 -> 161931.82 | AQ20: =+AL20+AP20 -> 9500000 | AR20: =N20-AQ20 -> 0 | AS20: =+AN20-AO20 -> 0 | AT20: 0 | AU20: =AT20*AC20 -> 0 | AV20: =+AQ20+AU20 -> 9500000 | AW20: =N20-AV20 -> 0 | AY20: =SUM(AZ20:BK20) -> 0 | AZ20: =+X20*0 -> 0 | BA20: =+X20*0 -> 0 | BB20: =+X20*0 -> 0 | BC20: =+X20*0 -> 0 | BD20: =+X20*0 -> 0 | BE20: =+X20*0 -> 0 | BF20: =+X20*0 -> 0 | BG20: =+X20*0 -> 0 | BH20: =+X20*0 -> 0 | BI20: =+X20*0 -> 0 | BJ20: =+X20*0 -> 0 | BK20: =+X20*0 -> 0
C21: 42107 | E21: Renovasi Gedung Lt.1 | G21: 0.1 | H21: 37000000 | K21: =H21+I21-J21 -> 37000000 | N21: =K21+L21-M21 -> 37000000 | O21: 4 | P21: =O21*12 -> 48 | Q21: =100%/G21 -> 10 | R21: =Q21*12 -> 120 | S21: =MONTH(C21) -> 4 | T21: =YEAR(C21) -> 2015 | U21: =IF(S21=1, 12, S21-1) -> 3 | V21: =IF(S21=1,T21+Q21-1,T21+Q21) -> 2025 | W21: =H21/P21 -> 770833.33 | X21: 210227.27 | Y21: 39 | Z21: 12 | AA21: =Z21*X21 -> 2522727.3 | AB21: 31323864 | AC21: =N21-AB21 -> 5676136.4 | AD21: =+Y21-Z21 -> 27 | AE21: 12 | AF21: =AE21*X21 -> 2522727.3 | AG21: =+AB21+AF21 -> 33846591 | AH21: =N21-AG21 -> 3153409.1 | AI21: =+AD21-AE21 -> 15 | AJ21: 12 | AK21: =AJ21*X21 -> 2522727.3 | AL21: =+AG21+AK21 -> 36369318 | AM21: =N21-AL21 -> 630681.82 | AN21: =+AI21-AJ21 -> 3 | AO21: 3 | AP21: =AO21*X21 -> 630681.82 | AQ21: =+AL21+AP21 -> 37000000 | AR21: =N21-AQ21 -> 0 | AS21: =+AN21-AO21 -> 0 | AT21: 0 | AU21: =AT21*AC21 -> 0 | AV21: =+AQ21+AU21 -> 37000000 | AW21: =N21-AV21 -> 0 | AY21: =SUM(AZ21:BK21) -> 0 | AZ21: =+X21*0 -> 0 | BA21: =+X21*0 -> 0 | BB21: =+X21*0 -> 0 | BC21: =+X21*0 -> 0 | BD21: =+X21*0 -> 0 | BE21: =+X21*0 -> 0 | BF21: =+X21*0 -> 0 | BG21: =+X21*0 -> 0 | BH21: =+X21*0 -> 0 | BI21: =+X21*0 -> 0 | BJ21: =+X21*0 -> 0 | BK21: =+X21*0 -> 0
C22: 42116 | E22: Renovasi Gedung Lt.1 | G22: 0.1 | H22: 68000000 | K22: =H22+I22-J22 -> 68000000 | N22: =K22+L22-M22 -> 68000000 | O22: 4 | P22: =O22*12 -> 48 | Q22: =100%/G22 -> 10 | R22: =Q22*12 -> 120 | S22: =MONTH(C22) -> 4 | T22: =YEAR(C22) -> 2015 | U22: =IF(S22=1, 12, S22-1) -> 3 | V22: =IF(S22=1,T22+Q22-1,T22+Q22) -> 2025 | W22: =H22/P22 -> 1416666.7 | X22: 386363.64 | Y22: 39 | Z22: 12 | AA22: =Z22*X22 -> 4636363.6 | AB22: 57568182 | AC22: =N22-AB22 -> 10431818 | AD22: =+Y22-Z22 -> 27 | AE22: 12 | AF22: =AE22*X22 -> 4636363.6 | AG22: =+AB22+AF22 -> 62204545 | AH22: =N22-AG22 -> 5795454.5 | AI22: =+AD22-AE22 -> 15 | AJ22: 12 | AK22: =AJ22*X22 -> 4636363.6 | AL22: =+AG22+AK22 -> 66840909 | AM22: =N22-AL22 -> 1159090.9 | AN22: =+AI22-AJ22 -> 3 | AO22: 3 | AP22: =AO22*X22 -> 1159090.9 | AQ22: =+AL22+AP22 -> 68000000 | AR22: =N22-AQ22 -> 0 | AS22: =+AN22-AO22 -> 0 | AT22: 0 | AU22: =AT22*AC22 -> 0 | AV22: =+AQ22+AU22 -> 68000000 | AW22: =N22-AV22 -> 0 | AY22: =SUM(AZ22:BK22) -> 0 | AZ22: =+X22*0 -> 0 | BA22: =+X22*0 -> 0 | BB22: =+X22*0 -> 0 | BC22: =+X22*0 -> 0 | BD22: =+X22*0 -> 0 | BE22: =+X22*0 -> 0 | BF22: =+X22*0 -> 0 | BG22: =+X22*0 -> 0 | BH22: =+X22*0 -> 0 | BI22: =+X22*0 -> 0 | BJ22: =+X22*0 -> 0 | BK22: =+X22*0 -> 0
C23: 42137 | E23: Renovasi Gedung Lt.1 | G23: 0.1 | H23: 35000000 | K23: =H23+I23-J23 -> 35000000 | N23: =K23+L23-M23 -> 35000000 | O23: 4 | P23: =O23*12 -> 48 | Q23: =100%/G23 -> 10 | R23: =Q23*12 -> 120 | S23: =MONTH(C23) -> 5 | T23: =YEAR(C23) -> 2015 | U23: =IF(S23=1, 12, S23-1) -> 4 | V23: =IF(S23=1,T23+Q23-1,T23+Q23) -> 2025 | W23: =H23/P23 -> 729166.67 | X23: 204166.67 | Y23: 40 | Z23: 12 | AA23: =Z23*X23 -> 2450000 | AB23: 29283333 | AC23: =N23-AB23 -> 5716666.7 | AD23: =+Y23-Z23 -> 28 | AE23: 12 | AF23: =AE23*X23 -> 2450000 | AG23: =+AB23+AF23 -> 31733333 | AH23: =N23-AG23 -> 3266666.7 | AI23: =+AD23-AE23 -> 16 | AJ23: 12 | AK23: =AJ23*X23 -> 2450000 | AL23: =+AG23+AK23 -> 34183333 | AM23: =N23-AL23 -> 816666.67 | AN23: =+AI23-AJ23 -> 4 | AO23: 4 | AP23: =AO23*X23 -> 816666.67 | AQ23: =+AL23+AP23 -> 35000000 | AR23: =N23-AQ23 -> 0 | AS23: =+AN23-AO23 -> 0 | AT23: 0 | AU23: =AT23*AC23 -> 0 | AV23: =+AQ23+AU23 -> 35000000 | AW23: =N23-AV23 -> 0 | AY23: =SUM(AZ23:BK23) -> 0 | AZ23: =+X23*0 -> 0 | BA23: =+X23*0 -> 0 | BB23: =+X23*0 -> 0 | BC23: =+X23*0 -> 0 | BD23: =+X23*0 -> 0 | BE23: =+X23*0 -> 0 | BF23: =+X23*0 -> 0 | BG23: =+X23*0 -> 0 | BH23: =+X23*0 -> 0 | BI23: =+X23*0 -> 0 | BJ23: =+X23*0 -> 0 | BK23: =+X23*0 -> 0
C24: 42247 | E24: Renovasi Gedung Lt.1 | G24: 0.1 | H24: 39250000 | K24: =H24+I24-J24 -> 39250000 | N24: =K24+L24-M24 -> 39250000 | O24: 4 | P24: =O24*12 -> 48 | Q24: =100%/G24 -> 10 | R24: =Q24*12 -> 120 | S24: =MONTH(C24) -> 8 | T24: =YEAR(C24) -> 2015 | U24: =IF(S24=1, 12, S24-1) -> 7 | V24: =IF(S24=1,T24+Q24-1,T24+Q24) -> 2025 | W24: =H24/P24 -> 817708.33 | X24: 246106.39 | Y24: 43 | Z24: 12 | AA24: =Z24*X24 -> 2953276.7 | AB24: 31620702 | AC24: =N24-AB24 -> 7629298.1 | AD24: =+Y24-Z24 -> 31 | AE24: 12 | AF24: =AE24*X24 -> 2953276.7 | AG24: =+AB24+AF24 -> 34573979 | AH24: =N24-AG24 -> 4676021.4 | AI24: =+AD24-AE24 -> 19 | AJ24: 12 | AK24: =AJ24*X24 -> 2953276.7 | AL24: =+AG24+AK24 -> 37527255 | AM24: =N24-AL24 -> 1722744.7 | AN24: =+AI24-AJ24 -> 7 | AO24: 7 | AP24: =AO24*X24 -> 1722744.7 | AQ24: =+AL24+AP24 -> 39250000 | AR24: =N24-AQ24 -> 0 | AS24: =+AN24-AO24 -> 0 | AT24: 0 | AU24: =AT24*AC24 -> 0 | AV24: =+AQ24+AU24 -> 39250000 | AW24: =N24-AV24 -> 0 | AY24: =SUM(AZ24:BK24) -> 0 | AZ24: =+X24*0 -> 0 | BA24: =+X24*0 -> 0 | BB24: =+X24*0 -> 0 | BC24: =+X24*0 -> 0 | BD24: =+X24*0 -> 0 | BE24: =+X24*0 -> 0 | BF24: =+X24*0 -> 0 | BG24: =+X24*0 -> 0 | BH24: =+X24*0 -> 0 | BI24: =+X24*0 -> 0 | BJ24: =+X24*0 -> 0 | BK24: =+X24*0 -> 0
C25: 42325 | E25: Renovasi Gedung Lt.1 | G25: 0.1 | H25: 3600000 | K25: =H25+I25-J25 -> 3600000 | N25: =K25+L25-M25 -> 3600000 | O25: 4 | P25: =O25*12 -> 48 | Q25: =100%/G25 -> 10 | R25: =Q25*12 -> 120 | S25: =MONTH(C25) -> 11 | T25: =YEAR(C25) -> 2015 | U25: =IF(S25=1, 12, S25-1) -> 10 | V25: =IF(S25=1,T25+Q25-1,T25+Q25) -> 2025 | W25: =H25/P25 -> 75000 | X25: 24056.604 | Y25: 46 | Z25: 12 | AA25: =Z25*X25 -> 288679.25 | AB25: 2782075.5 | AC25: =N25-AB25 -> 817924.53 | AD25: =+Y25-Z25 -> 34 | AE25: 12 | AF25: =AE25*X25 -> 288679.25 | AG25: =+AB25+AF25 -> 3070754.7 | AH25: =N25-AG25 -> 529245.28 | AI25: =+AD25-AE25 -> 22 | AJ25: 12 | AK25: =AJ25*X25 -> 288679.25 | AL25: =+AG25+AK25 -> 3359434 | AM25: =N25-AL25 -> 240566.04 | AN25: =+AI25-AJ25 -> 10 | AO25: 10 | AP25: =AO25*X25 -> 240566.04 | AQ25: =+AL25+AP25 -> 3600000 | AR25: =N25-AQ25 -> 0 | AS25: =+AN25-AO25 -> 0 | AT25: 0 | AU25: =AT25*AC25 -> 0 | AV25: =+AQ25+AU25 -> 3600000 | AW25: =N25-AV25 -> 0 | AY25: =SUM(AZ25:BK25) -> 0 | AZ25: =+X25*0 -> 0 | BA25: =+X25*0 -> 0 | BB25: =+X25*0 -> 0 | BC25: =+X25*0 -> 0 | BD25: =+X25*0 -> 0 | BE25: =+X25*0 -> 0 | BF25: =+X25*0 -> 0 | BG25: =+X25*0 -> 0 | BH25: =+X25*0 -> 0 | BI25: =+X25*0 -> 0 | BJ25: =+X25*0 -> 0 | BK25: =+X25*0 -> 0
C26: 42380 | E26: Renovasi Kantor Belakang-Progress-1 | G26: 0.1 | H26: 64000000 | K26: =H26+I26-J26 -> 64000000 | N26: =K26+L26-M26 -> 64000000 | O26: 4 | P26: =O26*12 -> 48 | Q26: =100%/G26 -> 10 | R26: =Q26*12 -> 120 | S26: =MONTH(C26) -> 1 | T26: =YEAR(C26) -> 2016 | U26: =IF(S26=1, 12, S26-1) -> 12 | V26: =IF(S26=1,T26+Q26-1,T26+Q26) -> 2025 | W26: =H26/P26 -> 1333333.3 | X26: 444444.44 | Y26: 48 | Z26: 12 | AA26: =Z26*X26 -> 5333333.3 | AB26: 48000000 | AC26: =N26-AB26 -> 16000000 | AD26: =+Y26-Z26 -> 36 | AE26: 12 | AF26: =AE26*X26 -> 5333333.3 | AG26: =+AB26+AF26 -> 53333333 | AH26: =N26-AG26 -> 10666667 | AI26: =+AD26-AE26 -> 24 | AJ26: 12 | AK26: =AJ26*X26 -> 5333333.3 | AL26: =+AG26+AK26 -> 58666667 | AM26: =N26-AL26 -> 5333333.3 | AN26: =+AI26-AJ26 -> 12 | AO26: 12 | AP26: =AO26*X26 -> 5333333.3 | AQ26: =+AL26+AP26 -> 64000000 | AR26: =N26-AQ26 -> 0 | AS26: =+AN26-AO26 -> 0 | AT26: 0 | AU26: =AT26*AC26 -> 0 | AV26: =+AQ26+AU26 -> 64000000 | AW26: =N26-AV26 -> 0 | AY26: =SUM(AZ26:BK26) -> 0 | AZ26: =+X26*0 -> 0 | BA26: =+X26*0 -> 0 | BB26: =+X26*0 -> 0 | BC26: =+X26*0 -> 0 | BD26: =+X26*0 -> 0 | BE26: =+X26*0 -> 0 | BF26: =+X26*0 -> 0 | BG26: =+X26*0 -> 0 | BH26: =+X26*0 -> 0 | BI26: =+X26*0 -> 0 | BJ26: =+X26*0 -> 0 | BK26: =+X26*0 -> 0
C27: 42411 | E27: Renovasi Kantor Belakang-Progress-2 | G27: 0.1 | H27: 64000000 | K27: =H27+I27-J27 -> 64000000 | N27: =K27+L27-M27 -> 64000000 | O27: 4 | P27: =O27*12 -> 48 | Q27: =100%/G27 -> 10 | R27: =Q27*12 -> 120 | S27: =MONTH(C27) -> 2 | T27: =YEAR(C27) -> 2016 | U27: =IF(S27=1, 12, S27-1) -> 1 | V27: =IF(S27=1,T27+Q27-1,T27+Q27) -> 2026 | W27: =H27/P27 -> 1333333.3 | X27: 452599.39 | Y27: 49 | Z27: 12 | AA27: =Z27*X27 -> 5431192.7 | AB27: 47253823 | AC27: =N27-AB27 -> 16746177 | AD27: =+Y27-Z27 -> 37 | AE27: 12 | AF27: =AE27*X27 -> 5431192.7 | AG27: =+AB27+AF27 -> 52685015 | AH27: =N27-AG27 -> 11314985 | AI27: =+AD27-AE27 -> 25 | AJ27: 12 | AK27: =AJ27*X27 -> 5431192.7 | AL27: =+AG27+AK27 -> 58116208 | AM27: =N27-AL27 -> 5883792 | AN27: =+AI27-AJ27 -> 13 | AO27: 12 | AP27: =AO27*X27 -> 5431192.7 | AQ27: =+AL27+AP27 -> 63547401 | AR27: =N27-AQ27 -> 452599.39 | AS27: =+AN27-AO27 -> 1 | AT27: 1 | AU27: =AT27*X27 -> 452599.39 | AV27: =+AQ27+AU27 -> 64000000 | AW27: =N27-AV27 -> 0 | AY27: =SUM(AZ27:BK27) -> 452599.39 | AZ27: =+X27*1 -> 452599.39 | BA27: =+X27*0 -> 0 | BB27: =+X27*0 -> 0 | BC27: =+X27*0 -> 0 | BD27: =+X27*0 -> 0 | BE27: =+X27*0 -> 0 | BF27: =+X27*0 -> 0 | BG27: =+X27*0 -> 0 | BH27: =+X27*0 -> 0 | BI27: =+X27*0 -> 0 | BJ27: =+X27*0 -> 0 | BK27: =+X27*0 -> 0
C28: 42426 | E28: Renovasi Kantor Belakang-Progress-3 | G28: 0.1 | H28: 64000000 | K28: =H28+I28-J28 -> 64000000 | N28: =K28+L28-M28 -> 64000000 | O28: 4 | P28: =O28*12 -> 48 | Q28: =100%/G28 -> 10 | R28: =Q28*12 -> 120 | S28: =MONTH(C28) -> 2 | T28: =YEAR(C28) -> 2016 | U28: =IF(S28=1, 12, S28-1) -> 1 | V28: =IF(S28=1,T28+Q28-1,T28+Q28) -> 2026 | W28: =H28/P28 -> 1333333.3 | X28: 452599.39 | Y28: 49 | Z28: 12 | AA28: =Z28*X28 -> 5431192.7 | AB28: 47253823 | AC28: =N28-AB28 -> 16746177 | AD28: =+Y28-Z28 -> 37 | AE28: 12 | AF28: =AE28*X28 -> 5431192.7 | AG28: =+AB28+AF28 -> 52685015 | AH28: =N28-AG28 -> 11314985 | AI28: =+AD28-AE28 -> 25 | AJ28: 12 | AK28: =AJ28*X28 -> 5431192.7 | AL28: =+AG28+AK28 -> 58116208 | AM28: =N28-AL28 -> 5883792 | AN28: =+AI28-AJ28 -> 13 | AO28: 12 | AP28: =AO28*X28 -> 5431192.7 | AQ28: =+AL28+AP28 -> 63547401 | AR28: =N28-AQ28 -> 452599.39 | AS28: =+AN28-AO28 -> 1 | AT28: 1 | AU28: =AT28*X28 -> 452599.39 | AV28: =+AQ28+AU28 -> 64000000 | AW28: =N28-AV28 -> 0 | AY28: =SUM(AZ28:BK28) -> 452599.39 | AZ28: =+X28*1 -> 452599.39 | BA28: =+X28*0 -> 0 | BB28: =+X28*0 -> 0 | BC28: =+X28*0 -> 0 | BD28: =+X28*0 -> 0 | BE28: =+X28*0 -> 0 | BF28: =+X28*0 -> 0 | BG28: =+X28*0 -> 0 | BH28: =+X28*0 -> 0 | BI28: =+X28*0 -> 0 | BJ28: =+X28*0 -> 0 | BK28: =+X28*0 -> 0
